Workbook

Sheet Master
A1: PUBLIC MUTUAL — FUND MASTER | Data: MFR February 2026 | 111 Qualified / 171 Total Funds
A2: FUND DETAILS | K2: SCREENING | N2: ANNUALISED RETURNS vs BENCHMARK (MFR FEB 2026) | AC2: ALPHA EFFICIENCY (Alpha / VF) | AH2: ASSET ALLOCATION (%) | AN2: GEOGRAPHICAL BREAKDOWN (%) | AZ2: SECTOR BREAKDOWN (%) | BK2: TOP 5 | BL2: META | BP2: ATH MOMENTUM
A3: Fund Name | B3: Abbr | C3: Series | D3: Fund Type | E3: Geography | F3: Objective | G3: Risk Level | H3: Distribution | I3: Size (RM M) | J3: Launch | K3: Status | L3: Beat (%) | M3: Periods | N3: YTD Fund (%) | O3: YTD Bench (%) | P3: YTD Alpha (%) | Q3: 1Y Fund (%) | R3: 1Y Bench (%) | S3: 1Y Alpha (%) | T3: 3Y Fund (%) | U3: 3Y Bench (%) | V3: 3Y Alpha (%) | W3: 5Y Fund (%) | X3: 5Y Bench (%) | Y3: 5Y Alpha (%) | Z3: 10Y Fund (%) | AA3: 10Y Bench (%) | AB3: 10Y Alpha (%) | AC3: AE YTD | AD3: AE 1Y | AE3: AE 3Y | AF3: AE 5Y | AG3: AE 10Y | AH3: Dom. Equity (%) | AI3: For. Equity (%) | AJ3: FI / Sukuk (%) | AK3: Money Mkt (%) | AL3: Deposits (%) | AM3: Alloc Other (%) | AN3: USA (%) | AO3: Taiwan (%) | AP3: Korea (%) | AQ3: Japan (%) | AR3: France (%) | AS3: Germany (%) | AT3: China (%) | AU3: Singapore (%) | AV3: Netherlands (%) | AW3: Indonesia (%) | AX3: Australia (%) | AY3: Geo Other (%) | AZ3: Industrial (%) | BA3: Technology (%) | BB3: Financial (%) | BC3: Comms (%) | BD3: Cons. Disc. (%) | BE3: Cons. Staples (%) | BF3: Utilities (%) | BG3: Energy (%) | BH3: Materials (%) | BI3: Real Estate (%) | BJ3: Sector Other (%) | BK3: Top 5 Holdings | BL3: VF | BM3: VC | BN3: Lipper Class | BO3: Benchmark | BP3: ATH NAV | BQ3: ATH Date | BR3: Cur NAV | BS3: Drawdown (%) | BT3: Days from ATH
A4: PUBLIC ISLAMIC SELECT TREASURES FUND | B4: PISTF | C4: Shariah | D4: Equity | E4: Malaysia | F4: Capital Growth | G4: 5 | H4: Incidental | I4: 1262.73 | J4: 26.02.2008 | K4: Qualified | L4: 100 | M4: 5/5 | N4: 5.86 | O4: 1.2 | P4: 4.66 | Q4: 18.31 | R4: 0.31 | S4: 18 | T4: 9.42 | U4: 1.36 | V4: 8.06 | W4: 2.81 | X4: -2.46 | Y4: 5.27 | Z4: 5.52 | AA4: 0.84 | AB4: 4.68 | AC4: =IF(OR(P4="",BL4="",BL4=0),"",P4/BL4) | AD4: =IF(OR(S4="",BL4="",BL4=0),"",S4/BL4) | AE4: =IF(OR(V4="",BL4="",BL4=0),"",V4/BL4) | AF4: =IF(OR(Y4="",BL4="",BL4=0),"",Y4/BL4) | AG4: =IF(OR(AB4="",BL4="",BL4=0),"",AB4/BL4) | AH4: 74.7 | AI4: 20.4 | AK4: 4.9 | AN4: 7 | AO4: 6.4 | AP4: 2.8 | AQ4: 4.2 | AZ4: 37.3 | BA4: 7.2 | BB4: 15.7 | BC4: 8.5 | BE4: 20.9 | BK4: TIME dotCom Berhad | KPJ Healthcare Berhad | Frontken Corporation Berhad | Vitrox Corporation Berhad | Farm Fresh Berhad | BL4: 9.1 | BM4: Moderate | BN4: Equity Malaysia Domestic | BP4: 0.4796 | BQ4: 2026-03-18 | BR4: 0.4702 | BS4: -1.96 | BT4: 19
A5: PUBLIC ISLAMIC EMERGING OPPORTUNITIES FUND | B5: PIEMOF | C5: Shariah | D5: Equity | E5: Malaysia | F5: Capital Growth | G5: 5 | H5: Incidental | I5: 104.43 | J5: 30.03.2016 | K5: Qualified | L5: 100 | M5: 4/4 | N5: 8.87 | O5: 1.14 | P5: 7.73 | Q5: 19.49 | R5: 0.73 | S5: 18.76 | T5: 8.86 | U5: 1.66 | V5: 7.2 | W5: 2.76 | X5: -1.83 | Y5: 4.59 | AC5: =IF(OR(P5="",BL5="",BL5=0),"",P5/BL5) | AD5: =IF(OR(S5="",BL5="",BL5=0),"",S5/BL5) | AE5: =IF(OR(V5="",BL5="",BL5=0),"",V5/BL5) | AF5: =IF(OR(Y5="",BL5="",BL5=0),"",Y5/BL5) | AG5: =IF(OR(AB5="",BL5="",BL5=0),"",AB5/BL5) | AH5: 71.8 | AI5: 21 | AK5: 7.2 | AN5: 7.1 | AO5: 5.7 | AP5: 3 | AQ5: 5.2 | AZ5: 35.1 | BB5: 11.6 | BD5: 5.1 | BE5: 21.7 | BG5: 7.5 | BK5: Spritzer Berhad | Gas Malaysia Berhad | Malayan Cement Berhad | Kinik Company | Shibaura Mechatronics Corporation | BL5: 8.5 | BM5: Moderate | BN5: Equity Malaysia Domestic | BP5: 0.3976 | BQ5: 2026-02-26 | BR5: 0.3703 | BS5: -6.87 | BT5: 39
A6: PUBLIC ASIA ITTIKAL FUND | B6: PAIF | C6: Shariah | D6: Equity | E6: Malaysia | F6: Capital Growth | G6: 5 | H6: Incidental | I6: 5179.3 | J6: 22.08.2006 | K6: Qualified | L6: 100 | M6: 5/5 | N6: 24.96 | O6: 16.63 | P6: 8.33 | Q6: 55.72 | R6: 32.88 | S6: 22.84 | T6: 22.06 | U6: 14.92 | V6: 7.14 | W6: 5.12 | X6: 2.91 | Y6: 2.21 | Z6: 9.82 | AA6: 7.79 | AB6: 2.03 | AC6: =IF(OR(P6="",BL6="",BL6=0),"",P6/BL6) | AD6: =IF(OR(S6="",BL6="",BL6=0),"",S6/BL6) | AE6: =IF(OR(V6="",BL6="",BL6=0),"",V6/BL6) | AF6: =IF(OR(Y6="",BL6="",BL6=0),"",Y6/BL6) | AG6: =IF(OR(AB6="",BL6="",BL6=0),"",AB6/BL6) | AI6: 94.6 | AK6: 5.4 | AN6: 3.4 | AO6: 30.6 | AP6: 41.4 | AQ6: 11.4 | AT6: 7.8 | AZ6: 26.8 | BA6: 54.7 | BC6: 13.1 | BK6: Samsung Electronics Company Limited | SK Hynix Incorporated | Taiwan Semiconductor Manufacturing Company Limited | HD Hyundai Electric Company Limited | Delta Electronics Incorporated | BL6: 19.5 | BM6: Very High | BN6: Equity Asia Pacific Asia | BO6: ThebenchmarkforPAIFisacompositeof30%KualaLumpurSyariahIndex(prior to 1 November 2007), 30% FTSE Bursa Malaysia EMAS Shariah Index (1 November 2007 to 29 April 2011), 30% FTSE Bursa Malaysia Hijrah Shariah Index (30April2011to29April2013),15%FTSEBursaMalaysiaHijrahShariahIndex (w.e.f. 30 April 2013), 15% customised indexbyS&P Dow Jones Indices, LLC based on top 20 constituents bymarket capitalisation of the S&P BMIShariah JapanIndex(w.e.f.30April2013)and70%DowJonesIslamicMarketAsiaEx- JapanIndexSM(priorto1January2009),70%S&PShariahBMIAsiaEx-Japan Index (w.e.f. 1 January 2009). UnderlyingindexdataaresourcedfromS&PDowJonesIndices,LLCandLipper and expressed in Ringgit terms. | BP6: 0.6503 | BQ6: 2026-02-26 | BR6: 0.5851 | BS6: -10.03 | BT6: 39
A7: PUBLIC SMALLCAP FUND | B7: P SmallCap | C7: Conventional | D7: Equity | E7: Malaysia | F7: Capital Growth | G7: 5 | H7: Incidental | I7: 1448.19 | J7: 13.06.2000 | K7: Qualified | L7: 100 | M7: 5/5 | N7: 3.52 | O7: -0.06 | P7: 3.58 | Q7: 16.01 | R7: -0.97 | S7: 16.98 | T7: 7.49 | U7: 0.7 | V7: 6.79 | W7: 4.37 | X7: -0.76 | Y7: 5.13 | Z7: 5.68 | AA7: 0.42 | AB7: 5.26 | AC7: =IF(OR(P7="",BL7="",BL7=0),"",P7/BL7) | AD7: =IF(OR(S7="",BL7="",BL7=0),"",S7/BL7) | AE7: =IF(OR(V7="",BL7="",BL7=0),"",V7/BL7) | AF7: =IF(OR(Y7="",BL7="",BL7=0),"",Y7/BL7) | AG7: =IF(OR(AB7="",BL7="",BL7=0),"",AB7/BL7) | AH7: 76.7 | AI7: 17.1 | AK7: 6.2 | AN7: 13 | AQ7: 4.1 | AZ7: 23.4 | BB7: 34.3 | BC7: 19.5 | BE7: 7 | BJ7: 5.7 | BK7: TIME dotCom Berhad | IGB Real Estate Investment Trust | Hong Leong Industries Berhad | Malaysian Pacific Industries Berhad | IGB Berhad | BL7: 7.8 | BM7: Moderate | BN7: Equity Malaysia Domestic 30% of the fund’s NAV | BP7: 1.1524 | BQ7: 2026-01-23 | BR7: 1.0475 | BS7: -9.1 | BT7: 73
A8: PUBLIC REGIONAL SECTOR FUND | B8: PRSEC | C8: Conventional | D8: Equity | E8: Malaysia | F8: Capital Growth | G8: 5 | H8: Incidental | I8: 571.04 | J8: 21.03.2006 | K8: Qualified | L8: 100 | M8: 5/5 | N8: 19.9 | O8: 10.69 | P8: 9.21 | Q8: 39.14 | R8: 26.12 | S8: 13.02 | T8: 20.85 | U8: 14.17 | V8: 6.68 | W8: 4.71 | X8: 2.39 | Y8: 2.32 | Z8: 8.53 | AA8: 7.39 | AB8: 1.14 | AC8: =IF(OR(P8="",BL8="",BL8=0),"",P8/BL8) | AD8: =IF(OR(S8="",BL8="",BL8=0),"",S8/BL8) | AE8: =IF(OR(V8="",BL8="",BL8=0),"",V8/BL8) | AF8: =IF(OR(Y8="",BL8="",BL8=0),"",Y8/BL8) | AG8: =IF(OR(AB8="",BL8="",BL8=0),"",AB8/BL8) | AH8: 1 | AI8: 93.2 | AK8: 5.8 | AO8: 30.2 | AP8: 36.2 | AQ8: 9.8 | AT8: 10.4 | AU8: 3.3 | AZ8: 20.2 | BA8: 51.2 | BB8: 8.7 | BC8: 14.1 | BK8: Samsung Electronics Company Limited | Taiwan Semiconductor Manufacturing Company Limited | SK Hynix Incorporated | HD Hyundai Electric Company Limited | Tencent Holdings Limited | BL8: 17 | BM8: Very High | BN8: Equity Asia Pacific Asia | BP8: 0.3772 | BQ8: 2026-02-26 | BR8: 0.3445 | BS8: -8.67 | BT8: 39
A9: PUBLIC ASIA PACIFIC FOCUS FUND | B9: PAPFF | C9: Conventional | D9: Equity | E9: Asia Pacific | F9: Capital Growth | G9: 5 | H9: Incidental | I9: 120.99 | J9: 30.11.2021 | K9: Qualified | L9: 100 | M9: 3/3 | N9: 19.16 | O9: 9.35 | P9: 9.81 | Q9: 43.85 | R9: 24.76 | S9: 19.09 | T9: 22.92 | U9: 16.43 | V9: 6.49 | AC9: =IF(OR(P9="",BL9="",BL9=0),"",P9/BL9) | AD9: =IF(OR(S9="",BL9="",BL9=0),"",S9/BL9) | AE9: =IF(OR(V9="",BL9="",BL9=0),"",V9/BL9) | AF9: =IF(OR(Y9="",BL9="",BL9=0),"",Y9/BL9) | AG9: =IF(OR(AB9="",BL9="",BL9=0),"",AB9/BL9) | AH9: 1 | AI9: 93.5 | AK9: 5.5 | AN9: 9.4 | AO9: 26.8 | AP9: 39.9 | AQ9: 8.7 | AT9: 8.7 | AZ9: 23 | BA9: 54.3 | BB9: 2.2 | BC9: 15 | BK9: Samsung Electronics Company Limited | SK Hynix Incorporated | Taiwan Semiconductor Manufacturing Company Limited | HD Hyundai Electric Company Limited | Alibaba Group Holding Limited - W | BL9: 18.5 | BM9: Very High | BN9: Equity Asia Pacific Asia | BO9: ThebenchmarkforPAPFFisacompositeof80%customisedindexbyS&PDow JonesIndices,LLCbasedonthetop30constituentsoftheS&PBMIAsiaEx-Japan Index, 10% Tokyo Stock Price Index (TOPIX) and 10% 3-Month Kuala Lumpur Interbank Offered Rate (KLIBOR). UnderlyingindexdataaresourcedfromS&PDowJonesIndices,LLC,Lipperand Bank Negara Malaysia and expressed in Ringgit terms. | BP9: 0.3651 | BQ9: 2026-02-26 | BR9: 0.3276 | BS9: -10.27 | BT9: 39
A10: PUBLIC STRATEGIC SMALLCAP FUND | B10: PSSCF | C10: Conventional | D10: Equity | E10: Malaysia | F10: Capital Growth | G10: 5 | H10: Incidental | I10: 455.28 | J10: 20.03.2012 | K10: Qualified | L10: 100 | M10: 5/5 | N10: 0.59 | O10: -0.06 | P10: 0.65 | Q10: 15.84 | R10: -0.97 | S10: 16.81 | T10: 6.7 | U10: 0.7 | V10: 6 | W10: 2.02 | X10: -0.76 | Y10: 2.78 | Z10: 4.05 | AA10: 0.42 | AB10: 3.63 | AC10: =IF(OR(P10="",BL10="",BL10=0),"",P10/BL10) | AD10: =IF(OR(S10="",BL10="",BL10=0),"",S10/BL10) | AE10: =IF(OR(V10="",BL10="",BL10=0),"",V10/BL10) | AF10: =IF(OR(Y10="",BL10="",BL10=0),"",Y10/BL10) | AG10: =IF(OR(AB10="",BL10="",BL10=0),"",AB10/BL10) | AH10: 76.7 | AI10: 18.4 | AK10: 4.9 | AN10: 14.1 | AQ10: 4.3 | AZ10: 39.3 | BB10: 14.3 | BC10: 14.5 | BE10: 14.5 | BJ10: 5.4 | BK10: Spritzer Berhad | Kelington Group Berhad | Meta Platforms Incorporated | Malaysian Pacific Industries Berhad | Alphabet Incorporated - Class A | BL10: 11.5 | BM10: High | BN10: Equity Malaysia Domestic 30% of the fund’s NAV | BO10: Index data are sourced from Lipper. | BP10: 0.4893 | BQ10: 2024-05-23 | BR10: 0.4036 | BS10: -17.51 | BT10: 683
A11: PUBLIC ISLAMIC ASIA DIVIDEND FUND | B11: PIADF | C11: Shariah | D11: Equity | E11: Asia | F11: Income | G11: 5 | H11: Annual | I11: 1686.97 | J11: 03.04.2007 | K11: Qualified | L11: 100 | M11: 5/5 | N11: 17.79 | O11: 14.96 | P11: 2.83 | Q11: 34.98 | R11: 30.36 | S11: 4.62 | T11: 18.53 | U11: 13.61 | V11: 4.92 | W11: 3.33 | X11: 2.84 | Y11: 0.49 | Z11: 8.41 | AA11: 6.94 | AB11: 1.47 | AC11: =IF(OR(P11="",BL11="",BL11=0),"",P11/BL11) | AD11: =IF(OR(S11="",BL11="",BL11=0),"",S11/BL11) | AE11: =IF(OR(V11="",BL11="",BL11=0),"",V11/BL11) | AF11: =IF(OR(Y11="",BL11="",BL11=0),"",Y11/BL11) | AG11: =IF(OR(AB11="",BL11="",BL11=0),"",AB11/BL11) | AH11: 1.8 | AI11: 84.6 | AK11: 13.6 | AN11: 4 | AO11: 20.4 | AP11: 39.7 | AT11: 12.1 | AX11: 3.6 | AZ11: 20.2 | BA11: 36.9 | BC11: 25.1 | BE11: 1.5 | BH11: 1.8 | BK11: Samsung Electronics Company Limited | SK Hynix Incorporated | Taiwan Semiconductor Manufacturing Company Limited | Alibaba Group Holding Limited - W | Hanwha Aerospace Company Limited | BL11: 14.9 | BM11: Very High | BN11: Equity Asia Pacific Asia | BP11: 0.5329 | BQ11: 2026-02-26 | BR11: 0.4982 | BS11: -6.51 | BT11: 39
A12: PUBLIC ISLAMIC SAVINGS FUND | B12: PISVF | C12: Shariah | D12: Equity | E12: Malaysia | F12: Income | G12: 4 | H12: Semi-Annual | I12: 486.59 | J12: 15.12.2011 | K12: Qualified | L12: 100 | M12: 5/5 | N12: 1.97 | O12: 0.96 | P12: 1.01 | Q12: 14.18 | R12: 6.76 | S12: 7.42 | T12: 9.01 | U12: 4.19 | V12: 4.82 | W12: 2.39 | X12: -0.72 | Y12: 3.11 | Z12: 4.64 | AA12: 0.35 | AB12: 4.29 | AC12: =IF(OR(P12="",BL12="",BL12=0),"",P12/BL12) | AD12: =IF(OR(S12="",BL12="",BL12=0),"",S12/BL12) | AE12: =IF(OR(V12="",BL12="",BL12=0),"",V12/BL12) | AF12: =IF(OR(Y12="",BL12="",BL12=0),"",Y12/BL12) | AG12: =IF(OR(AB12="",BL12="",BL12=0),"",AB12/BL12) | AH12: 76.5 | AI12: 17.3 | AK12: 6.2 | AN12: 8.9 | AO12: 2 | AP12: 6.4 | AZ12: 26.8 | BB12: 12.3 | BC12: 13.9 | BE12: 9.8 | BF12: 10.3 | BK12: Tenaga Nasional Berhad | Telekom Malaysia Berhad | Press Metal Aluminium Holdings Berhad | HD Hyundai Electric Company Limited | Malayan Cement Berhad | BL12: 9.2 | BM12: Moderate | BN12: Equity Malaysia Domestic | BP12: 0.4053 | BQ12: 2024-07-15 | BR12: 0.381 | BS12: -6 | BT12: 630
A13: PB GREATER CHINA A-SHARES FUND | B13: PBGCASF | C13: Conventional | D13: Equity | E13: Greater China | F13: Capital Growth | G13: 5 | H13: Incidental | I13: 543.83 | J13: 10.03.2020 | K13: Qualified | L13: 100 | M13: 4/4 | N13: -0.15 | O13: -1.59 | P13: 1.44 | Q13: 28.45 | R13: 4.87 | S13: 23.58 | T13: 11.29 | U13: 6.63 | V13: 4.66 | W13: 0.01 | X13: -0.97 | Y13: 0.97 | AC13: =IF(OR(P13="",BL13="",BL13=0),"",P13/BL13) | AD13: =IF(OR(S13="",BL13="",BL13=0),"",S13/BL13) | AE13: =IF(OR(V13="",BL13="",BL13=0),"",V13/BL13) | AF13: =IF(OR(Y13="",BL13="",BL13=0),"",Y13/BL13) | AG13: =IF(OR(AB13="",BL13="",BL13=0),"",AB13/BL13) | AI13: 90.5 | AK13: 9.5 | AN13: 2.3 | AO13: 24.9 | AT13: 63.3 | AZ13: 6.7 | BA13: 34.8 | BC13: 17.1 | BE13: 10 | BH13: 16 | BK13: Taiwan Semiconductor Manufacturing Company Limited | Zijin Mining Group Company Limited - A Shares (HKS) | Wanhua Chemical Group Company Limited - A Shares (HKS) | Kinik Company | NAURA Technology Group Company Limited - A Shares (HKS) | BL13: 19.3 | BM13: Very High | BN13: Equity Greater China Greater China | BO13: ThebenchmarkforPBGCASFisacompositeof50%S&PChinaA50Index,25% Hang Seng China Enterprises Index(HSCEI), 15% S&P Taiwan LargeCapIndex and 10% 3-Month Kuala Lumpur Interbank Offered Rate (KLIBOR). UnderlyingindexdataaresourcedfromLipper,S&PDowJonesIndices,LLCand Bank Negara Malaysia and expressed in Ringgit terms. | BP13: 0.3848 | BQ13: 2021-02-18 | BR13: 0.3143 | BS13: -18.32 | BT13: 1873
A14: PUBLIC ISLAMIC TREASURES GROWTH FUND | B14: PITGF | C14: Shariah | D14: Equity | E14: Malaysia | F14: Capital Growth | G14: 5 | H14: Incidental | I14: 283.97 | J14: 19.07.2011 | K14: Qualified | L14: 100 | M14: 5/5 | N14: 9.12 | O14: 1.14 | P14: 7.98 | Q14: 14.9 | R14: 0.73 | S14: 14.17 | T14: 6.06 | U14: 1.66 | V14: 4.4 | W14: 0.18 | X14: -1.83 | Y14: 2.01 | Z14: 3.87 | AA14: 1.18 | AB14: 2.69 | AC14: =IF(OR(P14="",BL14="",BL14=0),"",P14/BL14) | AD14: =IF(OR(S14="",BL14="",BL14=0),"",S14/BL14) | AE14: =IF(OR(V14="",BL14="",BL14=0),"",V14/BL14) | AF14: =IF(OR(Y14="",BL14="",BL14=0),"",Y14/BL14) | AG14: =IF(OR(AB14="",BL14="",BL14=0),"",AB14/BL14) | AH14: 76.8 | AI14: 18.7 | AK14: 4.5 | AN14: 7.6 | AO14: 5.8 | AQ14: 5.3 | AZ14: 34.1 | BB14: 12.4 | BC14: 8.2 | BE14: 18.9 | BJ14: 6.6 | BK14: Vitrox Corporation Berhad | TIME dotCom Berhad | QL Resources Berhad | Malaysian Pacific Industries Berhad | Bursa Malaysia Berhad | BL14: 9 | BM14: Moderate | BN14: Equity Malaysia Domestic | BO14: The benchmark for PITGF is a composite of 90% FTSE Bursa Malaysia EMAS Shariah Index (prior to 30 April 2013), 90% FTSE Bursa Malaysia Small Cap ShariahIndex(FBMSSC)(30April2013to29April2015),90%customisedindex byFTSEbasedontheconstituentswithmarketcapitalisationbelowRM6.0billion withintheFTSE BursaMalaysia EMAS ShariahIndex(w.e.f. 30April 2015)and 10% 3-Month Islamic Interbank Money Market (IIMM) rate. Underlying index data are sourced from FTSE International Limited, Lipper and Bank Negara Malaysia. | BP14: 0.4043 | BQ14: 2021-04-26 | BR14: 0.3611 | BS14: -10.69 | BT14: 1806
A15: PUBLIC SELECT TREASURES EQUITY FUND | B15: PSTEF | C15: Conventional | D15: Equity | E15: Malaysia | F15: Capital Growth | G15: 5 | H15: Incidental | I15: 415.66 | J15: 22.07.2015 | K15: Qualified | L15: 100 | M15: 5/5 | N15: 6.19 | O15: 3.11 | P15: 3.08 | Q15: 17.13 | R15: 4.05 | S15: 13.08 | T15: 10.41 | U15: 7.06 | V15: 3.35 | W15: 3.18 | X15: 2.05 | Y15: 1.13 | Z15: 7.48 | AA15: 2.78 | AB15: 4.7 | AC15: =IF(OR(P15="",BL15="",BL15=0),"",P15/BL15) | AD15: =IF(OR(S15="",BL15="",BL15=0),"",S15/BL15) | AE15: =IF(OR(V15="",BL15="",BL15=0),"",V15/BL15) | AF15: =IF(OR(Y15="",BL15="",BL15=0),"",Y15/BL15) | AG15: =IF(OR(AB15="",BL15="",BL15=0),"",AB15/BL15) | AH15: 74.2 | AI15: 22.5 | AK15: 3.3 | AN15: 4.9 | AO15: 14.2 | AS15: 3.4 | AZ15: 37.3 | BA15: 7.3 | BB15: 31.1 | BC15: 5 | BE15: 12.2 | BK15: Hon.Precision Incorporated | Kinik Company | IGB Real Estate Investment Trust | TIME dotCom Berhad | HEICO Corporation | BL15: 9.1 | BM15: Moderate | BN15: Equity Malaysia Domestic 25% of the fund’s NAV | BP15: 0.4539 | BQ15: 2026-02-25 | BR15: 0.421 | BS15: -7.25 | BT15: 40
A16: PUBLIC DIVIDEND SELECT FUND | B16: PDSF | C16: Conventional | D16: Equity | E16: Malaysia | F16: Income | G16: 4 | H16: Semi-Annual | I16: 866.73 | J16: 03.05.2005 | K16: Qualified | L16: 100 | M16: 5/5 | N16: 2.68 | O16: 2.48 | P16: 0.2 | Q16: 9.19 | R16: 7.73 | S16: 1.46 | T16: 9.59 | U16: 6.31 | V16: 3.28 | W16: 4.72 | X16: 2.09 | Y16: 2.63 | Z16: 3.59 | AA16: 1.31 | AB16: 2.28 | AC16: =IF(OR(P16="",BL16="",BL16=0),"",P16/BL16) | AD16: =IF(OR(S16="",BL16="",BL16=0),"",S16/BL16) | AE16: =IF(OR(V16="",BL16="",BL16=0),"",V16/BL16) | AF16: =IF(OR(Y16="",BL16="",BL16=0),"",Y16/BL16) | AG16: =IF(OR(AB16="",BL16="",BL16=0),"",AB16/BL16) | AH16: 76.3 | AI16: 17.9 | AK16: 5.8 | AN16: 12.5 | AR16: 5.4 | AZ16: 7.3 | BB16: 47.5 | BC16: 9.3 | BD16: 13.3 | BF16: 8.4 | BK16: Public Bank Berhad | Malayan Banking Berhad | CIMB Group Holdings Berhad | IGB Real Estate Investment Trust | Tenaga Nasional Berhad | BL16: 6.7 | BM16: Low | BN16: Equity Malaysia Income Domestic 30% of the fund’s NAV | BP16: 0.3542 | BQ16: 2007-10-31 | BR16: 0.2908 | BS16: -17.9 | BT16: 6732
A17: PUBLIC FOCUS SELECT FUND | B17: PFSF | C17: Conventional | D17: Equity | E17: United States | F17: Capital Growth | G17: 5 | H17: Incidental | I17: 491.8 | J17: 25.11.2004 | K17: Qualified | L17: 100 | M17: 5/5 | N17: 4.79 | O17: 4.4 | P17: 0.39 | Q17: 15.42 | R17: 5.44 | S17: 9.98 | T17: 12.56 | U17: 9.29 | V17: 3.27 | W17: 5.35 | X17: 2.56 | Y17: 2.79 | Z17: 5.43 | AA17: 3.19 | AB17: 2.24 | AC17: =IF(OR(P17="",BL17="",BL17=0),"",P17/BL17) | AD17: =IF(OR(S17="",BL17="",BL17=0),"",S17/BL17) | AE17: =IF(OR(V17="",BL17="",BL17=0),"",V17/BL17) | AF17: =IF(OR(Y17="",BL17="",BL17=0),"",Y17/BL17) | AG17: =IF(OR(AB17="",BL17="",BL17=0),"",AB17/BL17) | AH17: 74.9 | AI17: 22.4 | AK17: 2.7 | AN17: 5.4 | AO17: 15.3 | AS17: 1.7 | AZ17: 30.5 | BA17: 8.1 | BB17: 33.1 | BC17: 5.5 | BE17: 14.5 | BK17: Hon.Precision Incorporated | Kinik Company | QL Resources Berhad | LPI Capital Berhad | TIME dotCom Berhad | BL17: 7.7 | BM17: Low | BN17: Equity Malaysia Domestic 30% of the fund’s NAV | BO17: Kuala Lumpur Composite Index (prior to 30 April 2008). FTSE Bursa Malaysia Mid 70 Index (w.e.f. 30 April 2008). Underlying index data are sourced from Lipper. | BP17: 0.4139 | BQ17: 2026-02-26 | BR17: 0.3866 | BS17: -6.6 | BT17: 39
A18: PUBLIC FAR-EAST PROPERTY & RESORTS FUND | B18: PFEPRF | C18: Conventional | D18: Equity | E18: Asia Pacific | F18: Capital Growth | G18: 5 | H18: Annual | I18: 199.9 | J18: 10.07.2007 | K18: Qualified | L18: 100 | M18: 5/5 | N18: 9.04 | O18: 8.32 | P18: 0.72 | Q18: 15.68 | R18: 14.99 | S18: 0.69 | T18: 8.69 | U18: 5.7 | V18: 2.99 | W18: 4.05 | X18: 0.83 | Y18: 3.22 | Z18: 3.3 | AA18: 1.26 | AB18: 2.04 | AC18: =IF(OR(P18="",BL18="",BL18=0),"",P18/BL18) | AD18: =IF(OR(S18="",BL18="",BL18=0),"",S18/BL18) | AE18: =IF(OR(V18="",BL18="",BL18=0),"",V18/BL18) | AF18: =IF(OR(Y18="",BL18="",BL18=0),"",Y18/BL18) | AG18: =IF(OR(AB18="",BL18="",BL18=0),"",AB18/BL18) | AH18: 26.2 | AI18: 63.6 | AK18: 10.2 | AQ18: 20.4 | AT18: 7 | AU18: 2.3 | AX18: 18.3 | BI18: 89.8 | BK18: Sun Hung Kai Properties Limited | Goodman Group | China Resources Land Limited | IGB Real Estate Investment Trust | Mitsubishi Estate Company Limited | BL18: 9.5 | BM18: Moderate | BN18: Equity Sector Real Asia | BP18: 0.3479 | BQ18: 2013-05-20 | BR18: 0.2669 | BS18: -23.28 | BT18: 4704
A19: PUBLIC EMERGING OPPORTUNITIES FUND | B19: PEMOF | C19: Conventional | D19: Equity | E19: Malaysia | F19: Capital Growth | G19: 5 | H19: Incidental | I19: 151.06 | J19: 30.03.2016 | K19: Qualified | L19: 100 | M19: 4/4 | N19: 6.11 | O19: 2.66 | P19: 3.45 | Q19: 9.84 | R19: 0.58 | S19: 9.26 | T19: 9.06 | U19: 6.19 | V19: 2.87 | W19: 1.97 | X19: 1.73 | Y19: 0.24 | AC19: =IF(OR(P19="",BL19="",BL19=0),"",P19/BL19) | AD19: =IF(OR(S19="",BL19="",BL19=0),"",S19/BL19) | AE19: =IF(OR(V19="",BL19="",BL19=0),"",V19/BL19) | AF19: =IF(OR(Y19="",BL19="",BL19=0),"",Y19/BL19) | AG19: =IF(OR(AB19="",BL19="",BL19=0),"",AB19/BL19) | AH19: 74.3 | AI19: 22.8 | AK19: 2.9 | AN19: 5.3 | AO19: 14.7 | AS19: 2.8 | AZ19: 44.8 | BA19: 7.7 | BB19: 25.9 | BE19: 8.3 | BG19: 4.7 | BK19: Kelington Group Berhad | Hon.Precision Incorporated | Kinik Company | Sunway Real Estate Investment Trust | IGB Real Estate Investment Trust | BL19: 10.6 | BM19: High | BN19: Equity Malaysia Domestic 25% of the fund’s NAV | BP19: 0.5405 | BQ19: 2024-07-15 | BR19: 0.4885 | BS19: -9.62 | BT19: 630
A20: PB CHINA PACIFIC EQUITY FUND | B20: PBCPEF | C20: Conventional | D20: Equity | E20: Greater China | F20: Capital Growth | G20: 5 | H20: Incidental | I20: 241.62 | J20: 23.10.2007 | K20: Qualified | L20: 100 | M20: 5/5 | N20: 15.47 | O20: 7.97 | P20: 7.5 | Q20: 20.01 | R20: 19.44 | S20: 0.57 | T20: 13.31 | U20: 10.71 | V20: 2.6 | W20: -0.75 | X20: -1.53 | Y20: 0.78 | Z20: 8.03 | AA20: 6.82 | AB20: 1.21 | AC20: =IF(OR(P20="",BL20="",BL20=0),"",P20/BL20) | AD20: =IF(OR(S20="",BL20="",BL20=0),"",S20/BL20) | AE20: =IF(OR(V20="",BL20="",BL20=0),"",V20/BL20) | AF20: =IF(OR(Y20="",BL20="",BL20=0),"",Y20/BL20) | AG20: =IF(OR(AB20="",BL20="",BL20=0),"",AB20/BL20) | AI20: 86.9 | AK20: 13.1 | AN20: 4 | AO20: 30.8 | AP20: 21.7 | AQ20: 7.1 | AT20: 23.3 | AZ20: 17.9 | BA20: 49 | BB20: 4.3 | BC20: 13.5 | BD20: 2.2 | BK20: Samsung Electronics Company Limited | SK Hynix Incorporated | Taiwan Semiconductor Manufacturing Company Limited | Alibaba Group Holding Limited - W | Semiconductor Manufacturing International Corporation | BL20: 18 | BM20: Very High | BN20: Equity Asia Pacific Greater China | BO20: ThebenchmarkforPBCPEFisacompositeof70%HangSengChinaEnterprises Index (HSCEI) and 30% Hang Seng Index (HSI) (prior to 1 January 2009). MSCI Zhong Hua Index (1 January 2009 to 29 April 2015). 80%MSCIZhongHuaIndex(30April2015to29April2021),80%S&PChina& HongKongLargeMidCapIndex(30April 2021to28December2025),60%S&P China&HongKongLargeMidCapIndex(w.e.f.29December2025),10%KOSPI50 Index (30 April 2015 to 29 April 2016), 10% MSCI Korea Large Cap Index (30April2016to29April2021),10%S&PKoreaLargeCapIndex(30April2021to 28December2025),15%S&PKoreaLargeCapIndex(w.e.f.29December2025), 10% FTSE TWSE Taiwan50Index(30April 2015 to29 April 2016), 10% MSCI Taiwan Large Cap Index (30 April 2016 to 29 April 2021), 10% S&P Taiwan LargeCapIndex(30April2021to28December2025),15%S&PTaiwanLargeCap Index(w.e.f.29December2025)and10%3-MonthKualaLumpurInterbankOffered Rate (KLIBOR) (w.e.f. 29 December 2025). UnderlyingindexdataaresourcedfromS&PDowJonesIndices,LLC,Lipperand Bank Negara Malaysia and expressed in Ringgit terms. | BP20: 0.5343 | BQ20: 2021-02-17 | BR20: 0.3943 | BS20: -26.2 | BT20: 1874
A21: PUBLIC ADVANTAGE GROWTH EQUITY FUND | B21: PAVGEF | C21: Conventional | D21: Equity | E21: Malaysia | F21: Capital Growth | G21: 5 | H21: Incidental | I21: 19.45 | J21: 08.09.2015 | K21: Qualified | L21: 100 | M21: 5/5 | N21: 2.32 | O21: 2.17 | P21: 0.15 | Q21: 12.36 | R21: 9.01 | S21: 3.35 | T21: 7.62 | U21: 5.69 | V21: 1.93 | W21: 2.27 | X21: 1.7 | Y21: 0.57 | Z21: 4.51 | AA21: 0.37 | AB21: 4.14 | AC21: =IF(OR(P21="",BL21="",BL21=0),"",P21/BL21) | AD21: =IF(OR(S21="",BL21="",BL21=0),"",S21/BL21) | AE21: =IF(OR(V21="",BL21="",BL21=0),"",V21/BL21) | AF21: =IF(OR(Y21="",BL21="",BL21=0),"",Y21/BL21) | AG21: =IF(OR(AB21="",BL21="",BL21=0),"",AB21/BL21) | AH21: 76.8 | AI21: 12.4 | AK21: 10.8 | AN21: 5.5 | AO21: 3.6 | AT21: 3.3 | AZ21: 19.3 | BB21: 27.5 | BC21: 17.1 | BF21: 10.5 | BH21: 6.9 | BK21: Malayan Banking Berhad | Tenaga Nasional Berhad | UWC Berhad | Press Metal Aluminium Holdings Berhad | Telekom Malaysia Berhad | BL21: 11 | BM21: High | BN21: Equity Malaysia Domestic 25% of the fund’s NAV | BP21: 0.3454 | BQ21: 2026-01-27 | BR21: 0.3273 | BS21: -5.24 | BT21: 69
A22: PUBLIC ISLAMIC SECTOR SELECT FUND | B22: PISSF | C22: Shariah | D22: Equity | E22: Malaysia | F22: Capital Growth | G22: 4 | H22: Incidental | I22: 112.13 | J22: 13.11.2007 | K22: Qualified | L22: 100 | M22: 5/5 | N22: 2.62 | O22: 1 | P22: 1.62 | Q22: 7.07 | R22: 7.06 | S22: 0.01 | T22: 5.13 | U22: 4.2 | V22: 0.93 | W22: 1.73 | X22: -1.2 | Y22: 2.93 | Z22: 1.55 | AA22: -0.03 | AB22: 1.58 | AC22: =IF(OR(P22="",BL22="",BL22=0),"",P22/BL22) | AD22: =IF(OR(S22="",BL22="",BL22=0),"",S22/BL22) | AE22: =IF(OR(V22="",BL22="",BL22=0),"",V22/BL22) | AF22: =IF(OR(Y22="",BL22="",BL22=0),"",Y22/BL22) | AG22: =IF(OR(AB22="",BL22="",BL22=0),"",AB22/BL22) | AH22: 77 | AI22: 21.1 | AK22: 1.9 | AN22: 8.9 | AO22: 6.9 | AR22: 5.3 | AZ22: 26.9 | BC22: 23.7 | BE22: 16.3 | BF22: 10.2 | BG22: 8.6 | BK22: Tenaga Nasional Berhad | Sunway Construction Group Berhad | Telekom Malaysia Berhad | Gamuda Berhad | Malayan Cement Berhad | BL22: 8 | BM22: Moderate | BN22: Equity Malaysia Domestic | BO22: Index data are sourced from Lipper. | BP22: 0.3302 | BQ22: 2013-11-19 | BR22: 0.2763 | BS22: -16.32 | BT22: 4521
A23: PUBLIC ISLAMIC OPPORTUNITIES FUND | B23: PIOF | C23: Shariah | D23: Equity | E23: Malaysia | F23: Capital Growth | G23: 5 | H23: Incidental | I23: 1090.72 | J23: 28.06.2005 | K23: Qualified | L23: 100 | M23: 5/5 | N23: 1.51 | O23: -1.51 | P23: 3.02 | Q23: 1.63 | R23: -0.19 | S23: 1.82 | T23: 2.22 | U23: 1.3 | V23: 0.92 | W23: -0.79 | X23: -1 | Y23: 0.21 | Z23: 5.32 | AA23: 0.25 | AB23: 5.07 | AC23: =IF(OR(P23="",BL23="",BL23=0),"",P23/BL23) | AD23: =IF(OR(S23="",BL23="",BL23=0),"",S23/BL23) | AE23: =IF(OR(V23="",BL23="",BL23=0),"",V23/BL23) | AF23: =IF(OR(Y23="",BL23="",BL23=0),"",Y23/BL23) | AG23: =IF(OR(AB23="",BL23="",BL23=0),"",AB23/BL23) | AH23: 69.9 | AI23: 18.9 | AK23: 11.2 | AN23: 6.2 | AO23: 5.5 | AP23: 7.2 | AZ23: 39.9 | BA23: 14.5 | BB23: 11.4 | BC23: 5.6 | BD23: 6.9 | BK23: Kelington Group Berhad | Frontken Corporation Berhad | Taiwan Semiconductor Manufacturing Company Limited | Uchi Technologies Berhad | HD Hyundai Electric Company Limited | BL23: 11.1 | BM23: High | BN23: Equity Malaysia Domestic | BO23: Kuala Lumpur Syariah Index (prior to 1 November 2007). FTSE Bursa Malaysia EMAS Shariah Index (1 November 2007 to 29 April 2013). FTSE Bursa Malaysia Small Cap Shariah Index (w.e.f. 30 April 2013). Underlying index data are sourced from Lipper. | BP23: 0.714 | BQ23: 2021-11-19 | BR23: 0.5401 | BS23: -24.36 | BT23: 1599
A24: PUBLIC e-ASIA EVOLVING GROWTH FUND | B24: PeAEVGF | C24: Conventional | D24: Equity | E24: Asia | F24: Capital Growth | G24: 5 | H24: Incidental | I24: 764.28 | J24: 30.11.2021 | K24: Qualified | L24: 100 | M24: 3/3 | N24: 11.61 | O24: 9.41 | P24: 2.2 | Q24: 26.36 | R24: 25.4 | S24: 0.96 | T24: 17.64 | U24: 16.9 | V24: 0.74 | AC24: =IF(OR(P24="",BL24="",BL24=0),"",P24/BL24) | AD24: =IF(OR(S24="",BL24="",BL24=0),"",S24/BL24) | AE24: =IF(OR(V24="",BL24="",BL24=0),"",V24/BL24) | AF24: =IF(OR(Y24="",BL24="",BL24=0),"",Y24/BL24) | AG24: =IF(OR(AB24="",BL24="",BL24=0),"",AB24/BL24) | AH24: 1 | AI24: 85.2 | AK24: 13.8 | AN24: 11.6 | AO24: 19.2 | AP24: 22.2 | AS24: 1.6 | AT24: 30.6 | AZ24: 13.7 | BA24: 42.8 | BB24: 1 | BC24: 23.5 | BD24: 5.2 | BK24: Samsung Electronics Company Limited | Taiwan Semiconductor Manufacturing Company Limited | SK Hynix Incorporated | Unimicron Technology Corporation | Alibaba Group Holding Limited - W | BL24: 18.5 | BM24: Very High | BN24: Equity Asia Pacific ex- Asia | BO24: ThebenchmarkforPeAEVGFisacompositeof90%customisedindexbyS&PDow JonesIndices,LLCbasedonthetop30constituentsoftheS&PBMIAsiaEx-Japan Index and 10% 3-Month Kuala Lumpur Interbank Offered Rate (KLIBOR). Underlying indexdata are sourced from S&P Dow Jones Indices, LLC and Bank Negara Malaysia and expressed in Ringgit terms. | BP24: 0.3294 | BQ24: 2026-01-28 | BR24: 0.2974 | BS24: -9.71 | BT24: 68
A25: PUBLIC ISLAMIC SUSTAINABLE GROWTH FUND | B25: PISGRTF | C25: Shariah | D25: Equity | E25: Malaysia | F25: Capital Growth | G25: 4 | H25: Incidental | I25: 122.8 | J25: 04.06.2024 | K25: Qualified | L25: 100 | M25: 2/2 | N25: 1.12 | O25: 0.9 | P25: 0.22 | Q25: 10.94 | R25: 6.81 | S25: 4.13 | AC25: =IF(OR(P25="",BL25="",BL25=0),"",P25/BL25) | AD25: =IF(OR(S25="",BL25="",BL25=0),"",S25/BL25) | AE25: =IF(OR(V25="",BL25="",BL25=0),"",V25/BL25) | AF25: =IF(OR(Y25="",BL25="",BL25=0),"",Y25/BL25) | AG25: =IF(OR(AB25="",BL25="",BL25=0),"",AB25/BL25) | AH25: 75.6 | AI25: 16.4 | AK25: 8 | AN25: 8.1 | AO25: 5.7 | AT25: 2.6 | AZ25: 20.3 | BB25: 22.6 | BC25: 24.5 | BE25: 7.2 | BF25: 9.6 | BK25: Tenaga Nasional Berhad | Sunway Berhad | Telekom Malaysia Berhad | TIME dotCom Berhad | QL Resources Berhad | BO25: Index data are sourced from Lipper. | BP25: 0.2681 | BQ25: 2026-01-27 | BR25: 0.2479 | BS25: -7.53 | BT25: 69
A26: PUBLIC ISLAMIC GLOBAL SUSTAINABLE GROWTH FUND | B26: PISGSGF | C26: Shariah | D26: Equity | E26: Global | F26: Capital Growth | G26: 5 | H26: Incidental | I26: 722.51 | J26: 20.02.2024 | K26: Qualified | L26: 100 | M26: 2/2 | N26: 0.23 | O26: -0.05 | P26: 0.28 | Q26: 16.92 | R26: 8.28 | S26: 8.64 | AC26: =IF(OR(P26="",BL26="",BL26=0),"",P26/BL26) | AD26: =IF(OR(S26="",BL26="",BL26=0),"",S26/BL26) | AE26: =IF(OR(V26="",BL26="",BL26=0),"",V26/BL26) | AF26: =IF(OR(Y26="",BL26="",BL26=0),"",Y26/BL26) | AG26: =IF(OR(AB26="",BL26="",BL26=0),"",AB26/BL26) | AH26: 3.7 | AI26: 81.2 | AK26: 15.1 | AN26: 51 | AO26: 9.5 | AP26: 8.2 | AT26: 4.5 | AV26: 6.6 | BA26: 49.8 | BB26: 5.1 | BC26: 23.4 | BD26: 5 | BE26: 1.6 | BK26: Taiwan Semiconductor Manufacturing Company Limited | Alphabet Incorporated - Class A | Apple Incorporated | Meta Platforms Incorporated | ASML Holding N.V. - NYS | BO26: The benchmark for PISGSGF is a composite of 90% S&P Global 1200 ESG Shariah Index and 10% 3-Month Islamic Interbank Money Market (IIMM) rate. UnderlyingindexdataaresourcedfromS&PDowJonesIndices,LLCandBank Negara Malaysia and expressed in Ringgit terms. | BP26: 0.3218 | BQ26: 2025-10-29 | BR26: 0.2868 | BS26: -10.88 | BT26: 159
A27: PUBLIC CHINA SELECT FUND | B27: PCSF | C27: Conventional | D27: Equity | E27: Greater China | F27: Capital Growth | G27: 5 | H27: Incidental | I27: 879.09 | J27: 05.06.2007 | K27: Qualified | L27: 80 | M27: 4/5 | N27: 2.92 | O27: 3.47 | P27: -0.55 | Q27: 28.84 | R27: 11.24 | S27: 17.6 | T27: 18.19 | U27: 10.93 | V27: 7.26 | W27: 3.99 | X27: -0.61 | Y27: 4.6 | Z27: 9.4 | AA27: 7.19 | AB27: 2.21 | AC27: =IF(OR(P27="",BL27="",BL27=0),"",P27/BL27) | AD27: =IF(OR(S27="",BL27="",BL27=0),"",S27/BL27) | AE27: =IF(OR(V27="",BL27="",BL27=0),"",V27/BL27) | AF27: =IF(OR(Y27="",BL27="",BL27=0),"",Y27/BL27) | AG27: =IF(OR(AB27="",BL27="",BL27=0),"",AB27/BL27) | AI27: 94.8 | AK27: 5.2 | AN27: 19 | AO27: 49.7 | AT27: 26.1 | AZ27: 15.5 | BA27: 40.3 | BC27: 30.6 | BD27: 8.4 | BK27: Taiwan Semiconductor Manufacturing Company Limited | Asia Vital Components Company Limited | Elite Material Company Limited | Alibaba Group Holding Limited - W | Tencent Holdings Limited | BL27: 16.4 | BM27: Very High | BN27: Equity Greater China Greater China | BP27: 0.5153 | BQ27: 2026-03-18 | BR27: 0.5025 | BS27: -2.48 | BT27: 19
A28: PB GROWTH SEQUEL FUND | B28: PBGSQF | C28: Conventional | D28: Equity | E28: Malaysia | F28: Capital Growth | G28: 4 | H28: Incidental | I28: 64.33 | J28: 15.11.2011 | K28: Qualified | L28: 80 | M28: 4/5 | N28: -0.65 | O28: 2.17 | P28: -2.82 | Q28: 13.3 | R28: 9.01 | S28: 4.29 | T28: 11.49 | U28: 5.69 | V28: 5.8 | W28: 5.16 | X28: 1.7 | Y28: 3.46 | Z28: 4.3 | AA28: 0.37 | AB28: 3.93 | AC28: =IF(OR(P28="",BL28="",BL28=0),"",P28/BL28) | AD28: =IF(OR(S28="",BL28="",BL28=0),"",S28/BL28) | AE28: =IF(OR(V28="",BL28="",BL28=0),"",V28/BL28) | AF28: =IF(OR(Y28="",BL28="",BL28=0),"",Y28/BL28) | AG28: =IF(OR(AB28="",BL28="",BL28=0),"",AB28/BL28) | AH28: 76.3 | AI28: 15.3 | AK28: 8.4 | AN28: 10.4 | AO28: 4.9 | AZ28: 28.5 | BA28: 4.9 | BB28: 24.7 | BC28: 17.7 | BE28: 8.4 | BK28: Public Bank Berhad | Sunway Berhad | Southern Cable Group Berhad | QL Resources Berhad | Malayan Cement Berhad | BL28: 8.9 | BM28: Moderate | BN28: Equity Malaysia | BO28: Index data are sourced from Lipper. | BP28: 0.3784 | BQ28: 2026-01-27 | BR28: 0.3462 | BS28: -8.51 | BT28: 69
A29: PUBLIC ITTIKAL FUND | B29: P ITTIKAL | C29: Shariah | D29: Equity | E29: Malaysia | F29: Capital Growth | G29: 4 | H29: Incidental | I29: 3917.94 | J29: 10.04.1997 | K29: Qualified | L29: 80 | M29: 4/5 | N29: -0.51 | O29: 1 | P29: -1.51 | Q29: 12.12 | R29: 7.06 | S29: 5.06 | T29: 9.97 | U29: 4.2 | V29: 5.77 | W29: 4.75 | X29: -1.2 | Y29: 5.95 | Z29: 3.48 | AA29: -0.03 | AB29: 3.51 | AC29: =IF(OR(P29="",BL29="",BL29=0),"",P29/BL29) | AD29: =IF(OR(S29="",BL29="",BL29=0),"",S29/BL29) | AE29: =IF(OR(V29="",BL29="",BL29=0),"",V29/BL29) | AF29: =IF(OR(Y29="",BL29="",BL29=0),"",Y29/BL29) | AG29: =IF(OR(AB29="",BL29="",BL29=0),"",AB29/BL29) | AH29: 75 | AI29: 20.4 | AK29: 4.6 | AN29: 12.1 | AO29: 8.3 | BA29: 12 | BB29: 13.8 | BC29: 19.1 | BE29: 21 | BF29: 9.7 | BK29: Sunway Berhad | Tenaga Nasional Berhad | IHH Healthcare Berhad | Telekom Malaysia Berhad | QL Resources Berhad | BL29: 8.5 | BM29: Moderate | BN29: Equity Malaysia Domestic | BO29: Kuala Lumpur Syariah Index (prior to 1 November 2007). FTSE Bursa Malaysia EMAS Shariah Index (w.e.f. 1 November 2007). | BP29: 1.31 | BQ29: 2000-02-24 | BR29: 0.9298 | BS29: -29.02 | BT29: 9538
A30: PUBLIC SECTOR SELECT FUND | B30: PSSF | C30: Conventional | D30: Equity | E30: Malaysia | F30: Capital Growth | G30: 4 | H30: Incidental | I30: 378.83 | J30: 13.11.2007 | K30: Qualified | L30: 80 | M30: 4/5 | N30: 1.87 | O30: 2.7 | P30: -0.83 | Q30: 13.3 | R30: 8.15 | S30: 5.15 | T30: 11.21 | U30: 6.58 | V30: 4.63 | W30: 6.17 | X30: 1.93 | Y30: 4.24 | Z30: 5.51 | AA30: 1.04 | AB30: 4.47 | AC30: =IF(OR(P30="",BL30="",BL30=0),"",P30/BL30) | AD30: =IF(OR(S30="",BL30="",BL30=0),"",S30/BL30) | AE30: =IF(OR(V30="",BL30="",BL30=0),"",V30/BL30) | AF30: =IF(OR(Y30="",BL30="",BL30=0),"",Y30/BL30) | AG30: =IF(OR(AB30="",BL30="",BL30=0),"",AB30/BL30) | AH30: 76.2 | AI30: 19.6 | AK30: 4.2 | AN30: 14.3 | AR30: 3 | AT30: 2.3 | BA30: 7 | BB30: 44.9 | BC30: 17.4 | BE30: 8.9 | BF30: 5.9 | BK30: Malayan Banking Berhad | Public Bank Berhad | Telekom Malaysia Berhad | Meta Platforms Incorporated | NVIDIA Corporation | BL30: 6.1 | BM30: Low | BN30: Equity Malaysia Domestic 25% of the fund’s NAV | BP30: 0.3973 | BQ30: 2026-02-11 | BR30: 0.3729 | BS30: -6.14 | BT30: 54
A31: PUBLIC ISLAMIC SELECT ENTERPRISES FUND | B31: PISEF | C31: Shariah | D31: Equity | E31: Malaysia | F31: Capital Growth | G31: 4 | H31: Incidental | I31: 947.53 | J31: 14.08.2008 | K31: Qualified | L31: 80 | M31: 4/5 | N31: -1.86 | O31: 1 | P31: -2.86 | Q31: 10.46 | R31: 7.06 | S31: 3.4 | T31: 8.43 | U31: 4.2 | V31: 4.23 | W31: 3.11 | X31: -1.2 | Y31: 4.31 | Z31: 2.7 | AA31: -0.03 | AB31: 2.73 | AC31: =IF(OR(P31="",BL31="",BL31=0),"",P31/BL31) | AD31: =IF(OR(S31="",BL31="",BL31=0),"",S31/BL31) | AE31: =IF(OR(V31="",BL31="",BL31=0),"",V31/BL31) | AF31: =IF(OR(Y31="",BL31="",BL31=0),"",Y31/BL31) | AG31: =IF(OR(AB31="",BL31="",BL31=0),"",AB31/BL31) | AH31: 76.5 | AI31: 17.1 | AK31: 6.4 | AN31: 11 | AR31: 2.1 | AT31: 4 | AZ31: 12.4 | BC31: 17.4 | BE31: 19 | BF31: 9.7 | BG31: 8.3 | BK31: Tenaga Nasional Berhad | Telekom Malaysia Berhad | NVIDIA Corporation | Gamuda Berhad | Malayan Cement Berhad | BL31: 8.5 | BM31: Moderate | BN31: Equity Malaysia Domestic | BP31: 0.4479 | BQ31: 2014-07-07 | BR31: 0.415 | BS31: -7.35 | BT31: 4291
A32: PB SMALLCAP GROWTH FUND | B32: PBSCGF | C32: Conventional | D32: Equity | E32: Malaysia | F32: Capital Growth | G32: 5 | H32: Incidental | I32: 128.85 | J32: 13.01.2016 | K32: Qualified | L32: 80 | M32: 4/5 | N32: -0.21 | O32: 0.01 | P32: -0.22 | Q32: 15.79 | R32: -0.45 | S32: 16.24 | T32: 4.89 | U32: 1.06 | V32: 3.83 | W32: 2.29 | X32: -0.3 | Y32: 2.59 | Z32: 4.32 | AA32: 0.81 | AB32: 3.51 | AC32: =IF(OR(P32="",BL32="",BL32=0),"",P32/BL32) | AD32: =IF(OR(S32="",BL32="",BL32=0),"",S32/BL32) | AE32: =IF(OR(V32="",BL32="",BL32=0),"",V32/BL32) | AF32: =IF(OR(Y32="",BL32="",BL32=0),"",Y32/BL32) | AG32: =IF(OR(AB32="",BL32="",BL32=0),"",AB32/BL32) | AH32: 75.7 | AI32: 16.9 | AK32: 7.4 | AN32: 11.7 | AQ32: 5.2 | AZ32: 45.9 | BB32: 7.2 | BC32: 8.1 | BE32: 22.7 | BJ32: 6.3 | BK32: Spritzer Berhad | Malaysian Pacific Industries Berhad | Hume Cement Industries Berhad | Southern Cable Group Berhad | UWC Berhad | BL32: 11.6 | BM32: High | BN32: Equity Malaysia Small & | BO32: measure of fund performance. ThebenchmarkforPBSCGFisacompositeof90%FTSEBursaMalaysiaSmall Cap Index and 10% 3-Month Kuala Lumpur Interbank Offered Rate (KLIBOR). Underlying index data are sourced from Lipper and Bank Negara Malaysia. | BP32: 0.3595 | BQ32: 2024-06-14 | BR32: 0.3058 | BS32: -14.94 | BT32: 661
A33: PUBLIC CHINA TITANS FUND | B33: PCTF | C33: Conventional | D33: Equity | E33: Greater China | F33: Capital Growth | G33: 5 | H33: Incidental | I33: 895.94 | J33: 01.04.2008 | K33: Qualified | L33: 80 | M33: 4/5 | N33: 0.31 | O33: 2.62 | P33: -2.31 | Q33: 8.7 | R33: 7.86 | S33: 0.84 | T33: 16.33 | U33: 13.6 | V33: 2.73 | W33: 2.83 | X33: 2.11 | Y33: 0.72 | Z33: 8.24 | AA33: 6.53 | AB33: 1.71 | AC33: =IF(OR(P33="",BL33="",BL33=0),"",P33/BL33) | AD33: =IF(OR(S33="",BL33="",BL33=0),"",S33/BL33) | AE33: =IF(OR(V33="",BL33="",BL33=0),"",V33/BL33) | AF33: =IF(OR(Y33="",BL33="",BL33=0),"",Y33/BL33) | AG33: =IF(OR(AB33="",BL33="",BL33=0),"",AB33/BL33) | AI33: 84.6 | AK33: 15.4 | AN33: 7.9 | AO33: 31.5 | AT33: 7 | AZ33: 7.9 | BA33: 30.3 | BB33: 20.2 | BC33: 25.1 | BE33: 1.1 | BK33: Taiwan Semiconductor Manufacturing Company Limited | Alibaba Group Holding Limited - W | China Construction Bank Corporation - H Shares | Tencent Holdings Limited | Delta Electronics Incorporated | BL33: 16 | BM33: Very High | BN33: Equity Greater China Greater China | BO33: 2020 0.50 29.5.20 1.6 The benchmark for PCTF is a composite of 40% Hang Seng China Enterprises 2021 0.75 31.5.21 2.0 Index (HSCEI), 30% Hang Seng Index (HSI) and 30% FTSE TWSE Taiwan 50 Index(priorto30April2016),30%MSCITaiwanLargeCapIndex(30April2016to 2022 0.50 31.5.22 1.7 29 April 2021), 30% S&P Taiwan LargeCap Index (w.e.f. 30 April 2021). Note: Distribution yield simply measures the level of distributions and is UnderlyingindexdataaresourcedfromLipperandS&PDowJonesIndices,LLC not a measure of fund performance. and expressed in Ringgit terms. | BP33: 0.4627 | BQ33: 2025-10-03 | BR33: 0.4085 | BS33: -11.71 | BT33: 185
A34: PUBLIC ISLAMIC GROWTH & INCOME FUND | B34: PISGIF | C34: Shariah | D34: Equity | E34: Malaysia | F34: Capital Growth + Income | G34: 4 | H34: Annual | I34: 122.12 | J34: 07.01.2014 | K34: Qualified | L34: 80 | M34: 4/5 | N34: 1.05 | O34: 1 | P34: 0.05 | Q34: 6.87 | R34: 7.06 | S34: -0.19 | T34: 6.8 | U34: 4.2 | V34: 2.6 | W34: 2.19 | X34: -1.2 | Y34: 3.39 | Z34: 2.48 | AA34: -0.03 | AB34: 2.51 | AC34: =IF(OR(P34="",BL34="",BL34=0),"",P34/BL34) | AD34: =IF(OR(S34="",BL34="",BL34=0),"",S34/BL34) | AE34: =IF(OR(V34="",BL34="",BL34=0),"",V34/BL34) | AF34: =IF(OR(Y34="",BL34="",BL34=0),"",Y34/BL34) | AG34: =IF(OR(AB34="",BL34="",BL34=0),"",AB34/BL34) | AH34: 75.7 | AI34: 20.8 | AK34: 3.5 | AN34: 9.4 | AO34: 6.4 | AR34: 5 | AZ34: 13.2 | BB34: 18.8 | BC34: 22.4 | BF34: 10.2 | BG34: 10.7 | BK34: Tenaga Nasional Berhad | Telekom Malaysia Berhad | Gamuda Berhad | IHH Healthcare Berhad | Taiwan Semiconductor Manufacturing Company Limited | BL34: 6.2 | BM34: Low | BN34: Equity Malaysia Domestic | BO34: 2022 0.20 30.12.22 0.9 | BP34: 0.2735 | BQ34: 2025-10-02 | BR34: 0.2601 | BS34: -4.9 | BT34: 186
A35: PUBLIC STRATEGIC GROWTH FUND | B35: PSTGF | C35: Conventional | D35: Equity | E35: Malaysia | F35: Capital Growth | G35: 4 | H35: Incidental | I35: 388.9 | J35: 08.12.2014 | K35: Qualified | L35: 80 | M35: 4/5 | N35: 4.68 | O35: 2.55 | P35: 2.13 | Q35: 8.79 | R35: 10.23 | S35: -1.44 | T35: 10.73 | U35: 8.2 | V35: 2.53 | W35: 4.49 | X35: 3.41 | Y35: 1.08 | Z35: 8.23 | AA35: 4.01 | AB35: 4.22 | AC35: =IF(OR(P35="",BL35="",BL35=0),"",P35/BL35) | AD35: =IF(OR(S35="",BL35="",BL35=0),"",S35/BL35) | AE35: =IF(OR(V35="",BL35="",BL35=0),"",V35/BL35) | AF35: =IF(OR(Y35="",BL35="",BL35=0),"",Y35/BL35) | AG35: =IF(OR(AB35="",BL35="",BL35=0),"",AB35/BL35) | AH35: 61.2 | AI35: 18.9 | AK35: 19.9 | AN35: 6.2 | AO35: 4.9 | AP35: 7.8 | AZ35: 19.3 | BA35: 4.9 | BB35: 34.7 | BE35: 7.2 | BF35: 6.8 | BK35: Malayan Banking Berhad | Public Bank Berhad | Tenaga Nasional Berhad | HD Hyundai Electric Company Limited | Taiwan Semiconductor Manufacturing Company Limited | BL35: 6.9 | BM35: Low | BN35: Equity Malaysia Domestic 30% of the fund’s NAV | BO35: ThebenchmarkforPSTGFisacompositeof60%FTSEBursaMalaysiaKLCI,15% DowJonesIndustrialAverage,15%customisedindexbyMSCIbasedonthetop30 constituents of MSCI AC Far-East Ex-Japan Index (prior to 30 April 2021), 15% customisedindexbyS&PDowJonesIndices,LLCbasedonthetop30constituents oftheS&PBMIAsiaEx-JapanIndex(w.e.f.30April2021)and10%3-MonthKuala Lumpur Interbank Offered Rate (KLIBOR). UnderlyingindexdataaresourcedfromLipper,S&PDowJonesIndices,LLCand Bank Negara Malaysia and expressed in Ringgit terms. | BP35: 0.4912 | BQ35: 2026-02-26 | BR35: 0.4635 | BS35: -5.64 | BT35: 39
A36: PB ISLAMIC ASIA STRATEGIC SECTOR FUND | B36: PBIASSF | C36: Conventional | D36: Equity | E36: Asia | F36: Capital Growth | G36: 5 | H36: Incidental | I36: 100.08 | J36: 06.09.2007 | K36: Qualified | L36: 80 | M36: 4/5 | N36: 21.38 | O36: 19.33 | P36: 2.05 | Q36: 44.95 | R36: 37.52 | S36: 7.43 | T36: 18.24 | U36: 16.02 | V36: 2.22 | W36: 2.63 | X36: 3.33 | Y36: -0.7 | Z36: 9.23 | AA36: 8.69 | AB36: 0.54 | AC36: =IF(OR(P36="",BL36="",BL36=0),"",P36/BL36) | AD36: =IF(OR(S36="",BL36="",BL36=0),"",S36/BL36) | AE36: =IF(OR(V36="",BL36="",BL36=0),"",V36/BL36) | AF36: =IF(OR(Y36="",BL36="",BL36=0),"",Y36/BL36) | AG36: =IF(OR(AB36="",BL36="",BL36=0),"",AB36/BL36) | AI36: 91.6 | AK36: 8.4 | AO36: 37.7 | AP36: 35.7 | AQ36: 2.8 | AT36: 15.4 | AZ36: 23.8 | BA36: 49.4 | BC36: 16.7 | BE36: 1.7 | BK36: Samsung Electronics Company Limited | Taiwan Semiconductor Manufacturing Company Limited | SK Hynix Incorporated | HD Hyundai Electric Company Limited | Alibaba Group Holding Limited - W | BL36: 19.4 | BM36: Very High | BN36: Equity Asia Pacific Asia | BO36: ThebenchmarkforPBIASSFisacompositeof90%DowJonesIslamicMarketAsia Ex-JapanIndexSM(priorto1January2009),90%S&PShariahBMIAsiaEx-Japan Index(w.e.f. 1 January 2009) and 10% 3-Month Islamic Interbank MoneyMarket (IIMM) rate. Underlying indexdata are sourced from S&P Dow Jones Indices,LLC andBank Negara Malaysia and expressed in Ringgit terms. | BP36: 0.5211 | BQ36: 2026-02-26 | BR36: 0.4814 | BS36: -7.62 | BT36: 39
A37: PUBLIC CHINA ITTIKAL FUND | B37: PCIF | C37: Shariah | D37: Equity | E37: Malaysia | F37: Capital Growth | G37: 5 | H37: Incidental | I37: 748.66 | J37: 20.11.2007 | K37: Qualified | L37: 80 | M37: 4/5 | N37: 9.35 | O37: 3.94 | P37: 5.41 | Q37: 15.83 | R37: 7.12 | S37: 8.71 | T37: 13.36 | U37: 11.48 | V37: 1.88 | W37: 0.89 | X37: 0.69 | Y37: 0.2 | Z37: 7.58 | AA37: 7.89 | AB37: -0.31 | AC37: =IF(OR(P37="",BL37="",BL37=0),"",P37/BL37) | AD37: =IF(OR(S37="",BL37="",BL37=0),"",S37/BL37) | AE37: =IF(OR(V37="",BL37="",BL37=0),"",V37/BL37) | AF37: =IF(OR(Y37="",BL37="",BL37=0),"",Y37/BL37) | AG37: =IF(OR(AB37="",BL37="",BL37=0),"",AB37/BL37) | AI37: 92.3 | AK37: 7.7 | AN37: 4 | AO37: 58.8 | AP37: 1.6 | AT37: 27.9 | AZ37: 21.7 | BA37: 35.1 | BC37: 31.3 | BD37: 2.7 | BE37: 1.5 | BK37: Taiwan Semiconductor Manufacturing Company Limited | Alibaba Group Holding Limited - W | Unimicron Technology Corporation | Delta Electronics Incorporated | Asia Vital Components Company Limited | BL37: 15.5 | BM37: Very High | BN37: Equity Greater China Greater China | BO37: ThebenchmarkforPCIFisacompositeof50%DowJonesIslamicMarketHong KongIndexSM(priorto1January2009),50%S&PShariahBMIHongKongand China'H'SharesIndex(w.e.f.1January2009),30%DowJonesIslamicMarket TaiwanIndexSM(priorto1January2009),30%S&PShariahBMITaiwanIndex (w.e.f.1January2009)and20%FTSEBursaMalaysiaEMASShariahIndex(prior to30April2011),20%FTSEBursaMalaysiaHijrahShariahIndex(w.e.f.30April 2011). UnderlyingindexdataaresourcedfromS&PDowJonesIndices,LLCandLipper and expressed in Ringgit terms. | BP37: 0.4999 | BQ37: 2021-02-17 | BR37: 0.4656 | BS37: -6.86 | BT37: 1874
A38: PUBLIC SELECT ALPHA-30 FUND | B38: PSA30F | C38: Conventional | D38: Equity | E38: Malaysia | F38: Capital Growth | G38: 4 | H38: Incidental | I38: 56.18 | J38: 07.04.2009 | K38: Qualified | L38: 80 | M38: 4/5 | N38: 1.24 | O38: 2.17 | P38: -0.93 | Q38: 10.35 | R38: 9.01 | S38: 1.34 | T38: 7.37 | U38: 5.69 | V38: 1.68 | W38: 2.01 | X38: 1.7 | Y38: 0.31 | Z38: 4.25 | AA38: 0.37 | AB38: 3.88 | AC38: =IF(OR(P38="",BL38="",BL38=0),"",P38/BL38) | AD38: =IF(OR(S38="",BL38="",BL38=0),"",S38/BL38) | AE38: =IF(OR(V38="",BL38="",BL38=0),"",V38/BL38) | AF38: =IF(OR(Y38="",BL38="",BL38=0),"",Y38/BL38) | AG38: =IF(OR(AB38="",BL38="",BL38=0),"",AB38/BL38) | AH38: 76 | AI38: 19.8 | AK38: 4.2 | AN38: 14.5 | AR38: 2.4 | AT38: 2.9 | AZ38: 15.5 | BA38: 6.8 | BB38: 34.1 | BC38: 16.9 | BF38: 10 | BK38: Malayan Banking Berhad | Tenaga Nasional Berhad | Public Bank Berhad | Meta Platforms Incorporated | NVIDIA Corporation | BL38: 8 | BM38: Moderate | BN38: Equity Malaysia Domestic 30% of the fund’s NAV | BO38: Kuala Lumpur Composite Index (prior to 6 July 2009). FTSE Bursa Malaysia KLCI (w.e.f. 6 July 2009). | BP38: 0.3857 | BQ38: 2025-10-09 | BR38: 0.3639 | BS38: -5.65 | BT38: 179
A39: PUBLIC INDEX FUND | B39: PIX | C39: Shariah | D39: Equity | E39: Malaysia | F39: Capital Growth | G39: 4 | H39: Incidental | I39: 495.38 | J39: 02.03.1992 | K39: Qualified | L39: 80 | M39: 4/5 | N39: 1.08 | O39: 2.7 | P39: -1.62 | Q39: 11.45 | R39: 8.15 | S39: 3.3 | T39: 8.19 | U39: 6.58 | V39: 1.61 | W39: 4.04 | X39: 1.93 | Y39: 2.11 | Z39: 2.86 | AA39: 1.04 | AB39: 1.82 | AC39: =IF(OR(P39="",BL39="",BL39=0),"",P39/BL39) | AD39: =IF(OR(S39="",BL39="",BL39=0),"",S39/BL39) | AE39: =IF(OR(V39="",BL39="",BL39=0),"",V39/BL39) | AF39: =IF(OR(Y39="",BL39="",BL39=0),"",Y39/BL39) | AG39: =IF(OR(AB39="",BL39="",BL39=0),"",AB39/BL39) | AH39: 96.5 | AK39: 3.5 | AZ39: 11.7 | BB39: 46.8 | BC39: 10.2 | BE39: 13.3 | BF39: 9.7 | BK39: Public Bank Berhad | LPI Capital Berhad | Tenaga Nasional Berhad | Malayan Banking Berhad | CIMB Group Holdings Berhad | BL39: 7.8 | BM39: Moderate | BN39: Equity Malaysia 100% Domestic | BO39: Kuala Lumpur Composite Index (prior to 6 July 2009). FTSE Bursa Malaysia Top 100 Index (w.e.f. 6 July 2009). Underlying index data are sourced from Lipper. | BP39: 1.101 | BQ39: 2008-01-11 | BR39: 0.7036 | BS39: -36.09 | BT39: 6660
A40: PB GLOBAL TECHNOLOGY & HEALTHCARE FUND | B40: PBGTHF | C40: Conventional | D40: Equity | E40: Global | F40: Capital Growth | G40: 5 | H40: Incidental | I40: 477.57 | J40: 09.05.2019 | K40: Qualified | L40: 75 | M40: 3/4 | N40: 1.64 | O40: -1.75 | P40: 3.39 | Q40: 17.86 | R40: 6.21 | S40: 11.65 | T40: 22.13 | U40: 14.86 | V40: 7.27 | W40: 11.37 | X40: 11.4 | Y40: -0.03 | AC40: =IF(OR(P40="",BL40="",BL40=0),"",P40/BL40) | AD40: =IF(OR(S40="",BL40="",BL40=0),"",S40/BL40) | AE40: =IF(OR(V40="",BL40="",BL40=0),"",V40/BL40) | AF40: =IF(OR(Y40="",BL40="",BL40=0),"",Y40/BL40) | AG40: =IF(OR(AB40="",BL40="",BL40=0),"",AB40/BL40) | AI40: 91.5 | AK40: 8.5 | AN40: 45.2 | AO40: 14.7 | AP40: 19.1 | AT40: 5.7 | AV40: 4.6 | AZ40: 11.3 | BA40: 49.1 | BC40: 15.7 | BD40: 2 | BJ40: 13.4 | BK40: Samsung Electronics Company Limited | SK Hynix Incorporated | Apple Incorporated | Taiwan Semiconductor Manufacturing Company Limited | HD Hyundai Electric Company Limited | BL40: 15.5 | BM40: Very High | BN40: Equity Global Global | BO40: 2022 1.25 30.06.22 3.7 ThebenchmarkforPBGTHFisacompositeof50%S&PGlobal1200Information Note: Distribution yield simply measures the level of distributions and is not a TechnologyIndex, 40% S&P Global 1200 Health Care Index and 10% 1-Month measure of fund performance. Kuala Lumpur Interbank Offered Rate (KLIBOR). Underlying index data are sourced from Lipper and Bank Negara Malaysia and expressed in Ringgit terms. | BP40: 0.625 | BQ40: 2025-11-03 | BR40: 0.5658 | BS40: -9.47 | BT40: 154
...

Sheet Summary
A1: PUBLIC MUTUAL FUND SCREENER — SUMMARY | MFR February 2026
A3: SCREENING RESULTS
A4: Metric | B4: Value
A5: Total PHS files (all UT funds) | B5: 181
A6: Excluded: Class-B funds | B6: 6 | C6: (PeCDF-B, PMMF-B, PBCMF-B, PeICDF-B, PIMMF-B, PBICMF-B)
A7: Excluded: Wholesale funds | B7: 4 | C7: (PBCPF, PWSIF, PIWSIF, PeWS20F)
A8: Retail funds screened | B8: 171
A10: Funds qualified (≥60% beat rate) | B10: 111
A11: Funds disqualified | B11: 60
A12: Pass rate | B12: 64.9%
A13: Conventional funds qualified | B13: 67
A14: Shariah-compliant funds qualified | B14: 44
A16: Data source | B16: MFR February 2026
A17: Screening criteria | B17: ≥60% of YTD/1Y/3Y/5Y/10Y periods outperform benchmark
A18: Minimum data requirement | B18: ≥2 periods (YTD, 1Y, 3Y, 5Y, 10Y)
A19: Note | B19: Class-B & Wholesale funds excluded — not available to typical retail investors
A21: BREAKDOWN BY FUND TYPE
A22: Fund Type | B22: Qualified | C22: 100% Rate | D22: Shariah | E22: Conventional
A23: Equity | B23: =COUNTIFS(Master!K$4:K$174,"Qualified",Master!D$4:D$174,"Equity") | C23: =COUNTIFS(Master!K$4:K$174,"Qualified",Master!D$4:D$174,"Equity",Master!L$4:L$174,100) | D23: =COUNTIFS(Master!K$4:K$174,"Qualified",Master!D$4:D$174,"Equity",Master!C$4:C$174,"Shariah") | E23: =B23-D23
A24: Mixed Asset / Balanced | B24: =COUNTIFS(Master!K$4:K$174,"Qualified",Master!D$4:D$174,"Mixed Asset / Balanced") | C24: =COUNTIFS(Master!K$4:K$174,"Qualified",Master!D$4:D$174,"Mixed Asset / Balanced",Master!L$4:L$174,100) | D24: =COUNTIFS(Master!K$4:K$174,"Qualified",Master!D$4:D$174,"Mixed Asset / Balanced",Master!C$4:C$174,"Shariah") | E24: =B24-D24
A25: Fixed Income | B25: =COUNTIFS(Master!K$4:K$174,"Qualified",Master!D$4:D$174,"Fixed Income") | C25: =COUNTIFS(Master!K$4:K$174,"Qualified",Master!D$4:D$174,"Fixed Income",Master!L$4:L$174,100) | D25: =COUNTIFS(Master!K$4:K$174,"Qualified",Master!D$4:D$174,"Fixed Income",Master!C$4:C$174,"Shariah") | E25: =B25-D25
A26: Fund of Funds | B26: =COUNTIFS(Master!K$4:K$174,"Qualified",Master!D$4:D$174,"Fund of Funds") | C26: =COUNTIFS(Master!K$4:K$174,"Qualified",Master!D$4:D$174,"Fund of Funds",Master!L$4:L$174,100) | D26: =COUNTIFS(Master!K$4:K$174,"Qualified",Master!D$4:D$174,"Fund of Funds",Master!C$4:C$174,"Shariah") | E26: =B26-D26
A27: Money Market | B27: =COUNTIFS(Master!K$4:K$174,"Qualified",Master!D$4:D$174,"Money Market") | C27: =COUNTIFS(Master!K$4:K$174,"Qualified",Master!D$4:D$174,"Money Market",Master!L$4:L$174,100) | D27: =COUNTIFS(Master!K$4:K$174,"Qualified",Master!D$4:D$174,"Money Market",Master!C$4:C$174,"Shariah") | E27: =B27-D27
A28: TOTAL | B28: =SUM(B23:B27) | C28: =SUM(C23:C27) | D28: =SUM(D23:D27) | E28: =SUM(E23:E27)
A30: EQUITY — MEDIAN STATISTICS
A31: Metric | B31: YTD (%) | C31: 1Y (%) | D31: 3Y Ann. (%) | E31: 5Y Ann. (%) | F31: 10Y Ann. (%) | G31: 3Y Alpha (%) | H31: Beat (%)
A32: Median | B32: =IFERROR(MEDIAN(FILTER(Master!N$4:N$174,(Master!K$4:K$174="Qualified")*(Master!D$4:D$174="Equity"))),"") | C32: =IFERROR(MEDIAN(FILTER(Master!Q$4:Q$174,(Master!K$4:K$174="Qualified")*(Master!D$4:D$174="Equity"))),"") | D32: =IFERROR(MEDIAN(FILTER(Master!T$4:T$174,(Master!K$4:K$174="Qualified")*(Master!D$4:D$174="Equity"))),"") | E32: =IFERROR(MEDIAN(FILTER(Master!W$4:W$174,(Master!K$4:K$174="Qualified")*(Master!D$4:D$174="Equity"))),"") | F32: =IFERROR(MEDIAN(FILTER(Master!Z$4:Z$174,(Master!K$4:K$174="Qualified")*(Master!D$4:D$174="Equity"))),"") | G32: =IFERROR(MEDIAN(FILTER(Master!V$4:V$174,(Master!K$4:K$174="Qualified")*(Master!D$4:D$174="Equity"))),"") | H32: =IFERROR(MEDIAN(FILTER(Master!L$4:L$174,(Master!K$4:K$174="Qualified")*(Master!D$4:D$174="Equity"))),"")
A34: EQUITY — TOP 5 BY 3Y ANN. FUND RETURN
A35: Fund Name | B35: Abbr | C35: 3Y Fund (%) | D35: 3Y Alpha (%) | E35: Beat (%) | F35: AUM (RM M) | G35: VC
A36: =IFERROR(INDEX(SORT(FILTER({Master!A$4:A$174,Master!B$4:B$174,Master!T$4:T$174,Master!V$4:V$174,Master!L$4:L$174,Master!I$4:I$174,Master!BM$4:BM$174},Master!K$4:K$174="Qualified",Master!D$4:D$174="Equity",Master!T$4:T$174<>""),3,FALSE),1,1),"") | B36: =IFERROR(INDEX(SORT(FILTER({Master!A$4:A$174,Master!B$4:B$174,Master!T$4:T$174,Master!V$4:V$174,Master!L$4:L$174,Master!I$4:I$174,Master!BM$4:BM$174},Master!K$4:K$174="Qualified",Master!D$4:D$174="Equity",Master!T$4:T$174<>""),3,FALSE),1,2),"") | C36: =IFERROR(INDEX(SORT(FILTER({Master!A$4:A$174,Master!B$4:B$174,Master!T$4:T$174,Master!V$4:V$174,Master!L$4:L$174,Master!I$4:I$174,Master!BM$4:BM$174},Master!K$4:K$174="Qualified",Master!D$4:D$174="Equity",Master!T$4:T$174<>""),3,FALSE),1,3),"") | D36: =IFERROR(INDEX(SORT(FILTER({Master!A$4:A$174,Master!B$4:B$174,Master!T$4:T$174,Master!V$4:V$174,Master!L$4:L$174,Master!I$4:I$174,Master!BM$4:BM$174},Master!K$4:K$174="Qualified",Master!D$4:D$174="Equity",Master!T$4:T$174<>""),3,FALSE),1,4),"") | E36: =IFERROR(INDEX(SORT(FILTER({Master!A$4:A$174,Master!B$4:B$174,Master!T$4:T$174,Master!V$4:V$174,Master!L$4:L$174,Master!I$4:I$174,Master!BM$4:BM$174},Master!K$4:K$174="Qualified",Master!D$4:D$174="Equity",Master!T$4:T$174<>""),3,FALSE),1,5),"") | F36: =IFERROR(INDEX(SORT(FILTER({Master!A$4:A$174,Master!B$4:B$174,Master!T$4:T$174,Master!V$4:V$174,Master!L$4:L$174,Master!I$4:I$174,Master!BM$4:BM$174},Master!K$4:K$174="Qualified",Master!D$4:D$174="Equity",Master!T$4:T$174<>""),3,FALSE),1,6),"") | G36: =IFERROR(INDEX(SORT(FILTER({Master!A$4:A$174,Master!B$4:B$174,Master!T$4:T$174,Master!V$4:V$174,Master!L$4:L$174,Master!I$4:I$174,Master!BM$4:BM$174},Master!K$4:K$174="Qualified",Master!D$4:D$174="Equity",Master!T$4:T$174<>""),3,FALSE),1,7),"")
A37: =IFERROR(INDEX(SORT(FILTER({Master!A$4:A$174,Master!B$4:B$174,Master!T$4:T$174,Master!V$4:V$174,Master!L$4:L$174,Master!I$4:I$174,Master!BM$4:BM$174},Master!K$4:K$174="Qualified",Master!D$4:D$174="Equity",Master!T$4:T$174<>""),3,FALSE),2,1),"") | B37: =IFERROR(INDEX(SORT(FILTER({Master!A$4:A$174,Master!B$4:B$174,Master!T$4:T$174,Master!V$4:V$174,Master!L$4:L$174,Master!I$4:I$174,Master!BM$4:BM$174},Master!K$4:K$174="Qualified",Master!D$4:D$174="Equity",Master!T$4:T$174<>""),3,FALSE),2,2),"") | C37: =IFERROR(INDEX(SORT(FILTER({Master!A$4:A$174,Master!B$4:B$174,Master!T$4:T$174,Master!V$4:V$174,Master!L$4:L$174,Master!I$4:I$174,Master!BM$4:BM$174},Master!K$4:K$174="Qualified",Master!D$4:D$174="Equity",Master!T$4:T$174<>""),3,FALSE),2,3),"") | D37: =IFERROR(INDEX(SORT(FILTER({Master!A$4:A$174,Master!B$4:B$174,Master!T$4:T$174,Master!V$4:V$174,Master!L$4:L$174,Master!I$4:I$174,Master!BM$4:BM$174},Master!K$4:K$174="Qualified",Master!D$4:D$174="Equity",Master!T$4:T$174<>""),3,FALSE),2,4),"") | E37: =IFERROR(INDEX(SORT(FILTER({Master!A$4:A$174,Master!B$4:B$174,Master!T$4:T$174,Master!V$4:V$174,Master!L$4:L$174,Master!I$4:I$174,Master!BM$4:BM$174},Master!K$4:K$174="Qualified",Master!D$4:D$174="Equity",Master!T$4:T$174<>""),3,FALSE),2,5),"") | F37: =IFERROR(INDEX(SORT(FILTER({Master!A$4:A$174,Master!B$4:B$174,Master!T$4:T$174,Master!V$4:V$174,Master!L$4:L$174,Master!I$4:I$174,Master!BM$4:BM$174},Master!K$4:K$174="Qualified",Master!D$4:D$174="Equity",Master!T$4:T$174<>""),3,FALSE),2,6),"") | G37: =IFERROR(INDEX(SORT(FILTER({Master!A$4:A$174,Master!B$4:B$174,Master!T$4:T$174,Master!V$4:V$174,Master!L$4:L$174,Master!I$4:I$174,Master!BM$4:BM$174},Master!K$4:K$174="Qualified",Master!D$4:D$174="Equity",Master!T$4:T$174<>""),3,FALSE),2,7),"")
A38: =IFERROR(INDEX(SORT(FILTER({Master!A$4:A$174,Master!B$4:B$174,Master!T$4:T$174,Master!V$4:V$174,Master!L$4:L$174,Master!I$4:I$174,Master!BM$4:BM$174},Master!K$4:K$174="Qualified",Master!D$4:D$174="Equity",Master!T$4:T$174<>""),3,FALSE),3,1),"") | B38: =IFERROR(INDEX(SORT(FILTER({Master!A$4:A$174,Master!B$4:B$174,Master!T$4:T$174,Master!V$4:V$174,Master!L$4:L$174,Master!I$4:I$174,Master!BM$4:BM$174},Master!K$4:K$174="Qualified",Master!D$4:D$174="Equity",Master!T$4:T$174<>""),3,FALSE),3,2),"") | C38: =IFERROR(INDEX(SORT(FILTER({Master!A$4:A$174,Master!B$4:B$174,Master!T$4:T$174,Master!V$4:V$174,Master!L$4:L$174,Master!I$4:I$174,Master!BM$4:BM$174},Master!K$4:K$174="Qualified",Master!D$4:D$174="Equity",Master!T$4:T$174<>""),3,FALSE),3,3),"") | D38: =IFERROR(INDEX(SORT(FILTER({Master!A$4:A$174,Master!B$4:B$174,Master!T$4:T$174,Master!V$4:V$174,Master!L$4:L$174,Master!I$4:I$174,Master!BM$4:BM$174},Master!K$4:K$174="Qualified",Master!D$4:D$174="Equity",Master!T$4:T$174<>""),3,FALSE),3,4),"") | E38: =IFERROR(INDEX(SORT(FILTER({Master!A$4:A$174,Master!B$4:B$174,Master!T$4:T$174,Master!V$4:V$174,Master!L$4:L$174,Master!I$4:I$174,Master!BM$4:BM$174},Master!K$4:K$174="Qualified",Master!D$4:D$174="Equity",Master!T$4:T$174<>""),3,FALSE),3,5),"") | F38: =IFERROR(INDEX(SORT(FILTER({Master!A$4:A$174,Master!B$4:B$174,Master!T$4:T$174,Master!V$4:V$174,Master!L$4:L$174,Master!I$4:I$174,Master!BM$4:BM$174},Master!K$4:K$174="Qualified",Master!D$4:D$174="Equity",Master!T$4:T$174<>""),3,FALSE),3,6),"") | G38: =IFERROR(INDEX(SORT(FILTER({Master!A$4:A$174,Master!B$4:B$174,Master!T$4:T$174,Master!V$4:V$174,Master!L$4:L$174,Master!I$4:I$174,Master!BM$4:BM$174},Master!K$4:K$174="Qualified",Master!D$4:D$174="Equity",Master!T$4:T$174<>""),3,FALSE),3,7),"")
A39: =IFERROR(INDEX(SORT(FILTER({Master!A$4:A$174,Master!B$4:B$174,Master!T$4:T$174,Master!V$4:V$174,Master!L$4:L$174,Master!I$4:I$174,Master!BM$4:BM$174},Master!K$4:K$174="Qualified",Master!D$4:D$174="Equity",Master!T$4:T$174<>""),3,FALSE),4,1),"") | B39: =IFERROR(INDEX(SORT(FILTER({Master!A$4:A$174,Master!B$4:B$174,Master!T$4:T$174,Master!V$4:V$174,Master!L$4:L$174,Master!I$4:I$174,Master!BM$4:BM$174},Master!K$4:K$174="Qualified",Master!D$4:D$174="Equity",Master!T$4:T$174<>""),3,FALSE),4,2),"") | C39: =IFERROR(INDEX(SORT(FILTER({Master!A$4:A$174,Master!B$4:B$174,Master!T$4:T$174,Master!V$4:V$174,Master!L$4:L$174,Master!I$4:I$174,Master!BM$4:BM$174},Master!K$4:K$174="Qualified",Master!D$4:D$174="Equity",Master!T$4:T$174<>""),3,FALSE),4,3),"") | D39: =IFERROR(INDEX(SORT(FILTER({Master!A$4:A$174,Master!B$4:B$174,Master!T$4:T$174,Master!V$4:V$174,Master!L$4:L$174,Master!I$4:I$174,Master!BM$4:BM$174},Master!K$4:K$174="Qualified",Master!D$4:D$174="Equity",Master!T$4:T$174<>""),3,FALSE),4,4),"") | E39: =IFERROR(INDEX(SORT(FILTER({Master!A$4:A$174,Master!B$4:B$174,Master!T$4:T$174,Master!V$4:V$174,Master!L$4:L$174,Master!I$4:I$174,Master!BM$4:BM$174},Master!K$4:K$174="Qualified",Master!D$4:D$174="Equity",Master!T$4:T$174<>""),3,FALSE),4,5),"") | F39: =IFERROR(INDEX(SORT(FILTER({Master!A$4:A$174,Master!B$4:B$174,Master!T$4:T$174,Master!V$4:V$174,Master!L$4:L$174,Master!I$4:I$174,Master!BM$4:BM$174},Master!K$4:K$174="Qualified",Master!D$4:D$174="Equity",Master!T$4:T$174<>""),3,FALSE),4,6),"") | G39: =IFERROR(INDEX(SORT(FILTER({Master!A$4:A$174,Master!B$4:B$174,Master!T$4:T$174,Master!V$4:V$174,Master!L$4:L$174,Master!I$4:I$174,Master!BM$4:BM$174},Master!K$4:K$174="Qualified",Master!D$4:D$174="Equity",Master!T$4:T$174<>""),3,FALSE),4,7),"")
