Workbook

Sheet Master
A1: PUBLIC MUTUAL — FUND MASTER | Data: MFR April 2026 | 134 Qualified / 171 Total Funds
A2: FUND DETAILS | J2: SCREENING | O2: ANNUALISED RETURNS vs BENCHMARK (MFR FEB 2026) | AD2: ALPHA EFFICIENCY (Alpha / VF) | AI2: ASSET ALLOCATION (%) | AO2: GEOGRAPHICAL BREAKDOWN (%) | BA2: SECTOR BREAKDOWN (%) | BL2: TOP 5 | BM2: META | BQ2: ATH MOMENTUM
A3: Fund Name | B3: Abbr | C3: Shariah-compliant | D3: Fund Type | E3: Objective | F3: Risk Level | G3: Distribution | H3: Size (RM M) | I3: Launch | J3: Status | K3: Beat (%) | L3: Periods | M3: Rationale | N3: Wtd Alpha (%) | O3: YTD Fund (%) | P3: YTD Bench (%) | Q3: YTD Alpha (%) | R3: 1Y Fund (%) | S3: 1Y Bench (%) | T3: 1Y Alpha (%) | U3: 3Y Fund (%) | V3: 3Y Bench (%) | W3: 3Y Alpha (%) | X3: 5Y Fund (%) | Y3: 5Y Bench (%) | Z3: 5Y Alpha (%) | AA3: 10Y Fund (%) | AB3: 10Y Bench (%) | AC3: 10Y Alpha (%) | AD3: AE YTD | AE3: AE 1Y | AF3: AE 3Y | AG3: AE 5Y | AH3: AE 10Y | AI3: Dom. Equity (%) | AJ3: For. Equity (%) | AK3: FI / Sukuk (%) | AL3: Money Mkt (%) | AM3: Deposits (%) | AN3: Alloc Other (%) | AO3: USA (%) | AP3: Taiwan (%) | AQ3: Korea (%) | AR3: Japan (%) | AS3: France (%) | AT3: Germany (%) | AU3: China (%) | AV3: Singapore (%) | AW3: Netherlands (%) | AX3: Indonesia (%) | AY3: Australia (%) | AZ3: Geo Other (%) | BA3: Industrial (%) | BB3: Technology (%) | BC3: Financial (%) | BD3: Comms (%) | BE3: Cons. Disc. (%) | BF3: Cons. Staples (%) | BG3: Utilities (%) | BH3: Energy (%) | BI3: Materials (%) | BJ3: Real Estate (%) | BK3: Sector Other (%) | BL3: Top 5 Holdings | BM3: VF | BN3: VC | BO3: Lipper Class | BP3: Benchmark | BQ3: ATH NAV | BR3: ATH Date | BS3: Cur NAV | BT3: Drawdown (%) | BU3: Days from ATH
A4: PUBLIC ASIA PACIFIC FOCUS FUND | B4: PAPFF | C4: Conventional | D4: Equity | E4: Capital Growth | F4: 5 | G4: Incidental | H4: 132.41 | I4: 30.11.2021 | J4: Qualified | K4: 100 | L4: 3/3 | M4: Qualified (WA: +19.55%) — YTD✔ 1Y✔ 3Y✔ | N4: 19.55 | O4: 33.32 | P4: 12.92 | Q4: 20.4 | R4: 84.84 | S4: 39.58 | T4: 45.26 | U4: 27.63 | V4: 17.82 | W4: 9.81 | AD4: =IF(OR(Q4="",BM4="",BM4=0),"",Q4/BM4) | AE4: =IF(OR(T4="",BM4="",BM4=0),"",T4/BM4) | AF4: =IF(OR(W4="",BM4="",BM4=0),"",W4/BM4) | AG4: =IF(OR(Z4="",BM4="",BM4=0),"",Z4/BM4) | AH4: =IF(OR(AC4="",BM4="",BM4=0),"",AC4/BM4) | AI4: 0.8 | AJ4: 92.3 | AL4: 6.9 | AO4: 10.2 | AP4: 32.6 | AQ4: 34.6 | AR4: 7.7 | AU4: 7.2 | BA4: 24.4 | BB4: 52 | BC4: 2 | BD4: 14.7 | BL4: SK Hynix Incorporated | Taiwan Semiconductor Manufacturing Company Limited | Samsung Electronics Company Limited | HD Hyundai Electric Company Limited | Hanwha Aerospace Company Limited | BM4: 20.2 | BN4: Very High | BO4: Equity Asia Pacific Asia | BP4: ThebenchmarkforPAPFFisacompositeof80%customisedindexbyS&PDow JonesIndices,LLCbasedonthetop30constituentsoftheS&PBMIAsiaEx-Japan Index, 10% Tokyo Stock Price Index (TOPIX) and 10% 3-Month Kuala Lumpur Interbank Offered Rate (KLIBOR). UnderlyingindexdataaresourcedfromS&PDowJonesIndices,LLC,Lipperand Bank Negara Malaysia and expressed in Ringgit terms. | BQ4: 0.475 | BR4: 2026-06-04 | BS4: 0.46 | BT4: -3.16 | BU4: 11
A5: PUBLIC CHINA SELECT FUND | B5: PCSF | C5: Conventional | D5: Equity | E5: Capital Growth | F5: 5 | G5: Incidental | H5: 1054.97 | I5: 05.06.2007 | J5: Qualified | K5: 100 | L5: 5/5 | M5: Qualified (WA: +18.36%) — YTD✔ 1Y✔ 3Y✔ 5Y✔ 10Y✔ | N5: 18.36 | O5: 28.22 | P5: 7.04 | Q5: 21.18 | R5: 83.16 | S5: 26.81 | T5: 56.35 | U5: 27.21 | V5: 12.44 | W5: 14.77 | X5: 8.99 | Y5: -0.18 | Z5: 9.17 | AA5: 11.89 | AB5: 7.55 | AC5: 4.34 | AD5: =IF(OR(Q5="",BM5="",BM5=0),"",Q5/BM5) | AE5: =IF(OR(T5="",BM5="",BM5=0),"",T5/BM5) | AF5: =IF(OR(W5="",BM5="",BM5=0),"",W5/BM5) | AG5: =IF(OR(Z5="",BM5="",BM5=0),"",Z5/BM5) | AH5: =IF(OR(AC5="",BM5="",BM5=0),"",AC5/BM5) | AJ5: 97.2 | AL5: 2.8 | AO5: 18.8 | AP5: 58.3 | AU5: 20.1 | BA5: 25.9 | BB5: 34.8 | BD5: 28.8 | BE5: 7.7 | BL5: Elite Material Company Limited | Asia Vital Components Company Limited | Jentech Precision Industrial Company Limited | Taiwan Semiconductor Manufacturing Company Limited | Alphabet Incorporated - Class A | BM5: 16.2 | BN5: Very High | BO5: Equity Greater China Greater China | BQ5: 0.6555 | BR5: 2026-06-03 | BS5: 0.6216 | BT5: -5.17 | BU5: 12
A6: PUBLIC CHINA ITTIKAL FUND | B6: PCIF | C6: Shariah | D6: Equity | E6: Capital Growth | F6: 5 | G6: Incidental | H6: 923.46 | I6: 20.11.2007 | J6: Qualified | K6: 100 | L6: 5/5 | M6: Qualified (WA: +14.74%) — YTD✔ 1Y✔ 3Y✔ 5Y✔ 10Y✔ | N6: 14.74 | O6: 40.62 | P6: 7.79 | Q6: 32.83 | R6: 72.7 | S6: 23.44 | T6: 49.26 | U6: 24.34 | V6: 13.8 | W6: 10.54 | X6: 5.56 | Y6: 0.86 | Z6: 4.7 | AA6: 10.52 | AB6: 8.37 | AC6: 2.15 | AD6: =IF(OR(Q6="",BM6="",BM6=0),"",Q6/BM6) | AE6: =IF(OR(T6="",BM6="",BM6=0),"",T6/BM6) | AF6: =IF(OR(W6="",BM6="",BM6=0),"",W6/BM6) | AG6: =IF(OR(Z6="",BM6="",BM6=0),"",Z6/BM6) | AH6: =IF(OR(AC6="",BM6="",BM6=0),"",AC6/BM6) | AJ6: 96 | AL6: 4 | AO6: 3.9 | AP6: 70 | AQ6: 3 | AU6: 19.1 | BA6: 28.6 | BB6: 38.7 | BD6: 24.9 | BE6: 2.6 | BF6: 1.2 | BL6: Unimicron Technology Corporation | Taiwan Semiconductor Manufacturing Company Limited | Asia Vital Components Company Limited | Delta Electronics Incorporated | Accton Technology Corporation | BM6: 15.5 | BN6: Very High | BO6: Equity Greater China Greater China | BQ6: 0.6841 | BR6: 2026-06-03 | BS6: 0.643 | BT6: -6.01 | BU6: 12
A7: PUBLIC ISLAMIC REGIONAL ESG FUND | B7: PIRESGF | C7: Shariah | D7: Equity | E7: Capital Growth | F7: 5 | G7: Incidental | H7: 223.79 | I7: 07.11.2023 | J7: Qualified | K7: 100 | L7: 2/2 | M7: Qualified (WA: +14.22%) — YTD✔ 1Y✔ | N7: 14.22 | O7: 30.44 | P7: 23.61 | Q7: 6.83 | R7: 76.57 | S7: 59.89 | T7: 16.68 | AD7: =IF(OR(Q7="",BM7="",BM7=0),"",Q7/BM7) | AE7: =IF(OR(T7="",BM7="",BM7=0),"",T7/BM7) | AF7: =IF(OR(W7="",BM7="",BM7=0),"",W7/BM7) | AG7: =IF(OR(Z7="",BM7="",BM7=0),"",Z7/BM7) | AH7: =IF(OR(AC7="",BM7="",BM7=0),"",AC7/BM7) | AJ7: 87.3 | AL7: 12.7 | AO7: 7.8 | AP7: 28.3 | AQ7: 30.7 | AR7: 14.3 | AU7: 6.2 | BA7: 25.6 | BB7: 39.7 | BD7: 18.3 | BE7: 3.7 | BL7: SK Hynix Incorporated | HD Hyundai Electric Company Limited | Delta Electronics Incorporated | Taiwan Semiconductor Manufacturing Company Limited | Samsung Electronics Company Limited | BP7: ThebenchmarkforPIRESGFisacustomisedindexbyS&PDowJonesIndices, LLCbasedonconstituentsoftheS&PGlobalLargeMidCapESGShariahIndex comprisingJapan,China‘H’Shares,HongKong,Taiwan,SouthKorea,Malaysia, Singapore, Thailand, Indonesia & Philippines. Underlying index data are sourced from S&P Dow Jones Indices, LLC and expressed in Ringgit terms. | BQ7: 0.5179 | BR7: 2026-06-04 | BS7: 0.5049 | BT7: -2.51 | BU7: 11
A8: PUBLIC REGIONAL SECTOR FUND | B8: PRSEC | C8: Conventional | D8: Equity | E8: Capital Growth | F8: 5 | G8: Incidental | H8: 653.11 | I8: 21.03.2006 | J8: Qualified | K8: 100 | L8: 5/5 | M8: Qualified (WA: +13.81%) — YTD✔ 1Y✔ 3Y✔ 5Y✔ 10Y✔ | N8: 13.81 | O8: 35.22 | P8: 12.52 | Q8: 22.7 | R8: 80.56 | S8: 37.33 | T8: 43.23 | U8: 26.15 | V8: 14.67 | W8: 11.48 | X8: 7.27 | Y8: 2.35 | Z8: 4.92 | AA8: 9.86 | AB8: 7.38 | AC8: 2.48 | AD8: =IF(OR(Q8="",BM8="",BM8=0),"",Q8/BM8) | AE8: =IF(OR(T8="",BM8="",BM8=0),"",T8/BM8) | AF8: =IF(OR(W8="",BM8="",BM8=0),"",W8/BM8) | AG8: =IF(OR(Z8="",BM8="",BM8=0),"",Z8/BM8) | AH8: =IF(OR(AC8="",BM8="",BM8=0),"",AC8/BM8) | AI8: 0.8 | AJ8: 92.4 | AL8: 6.8 | AP8: 36.1 | AQ8: 32.8 | AR8: 8.5 | AU8: 8.6 | AV8: 3 | BA8: 20.9 | BB8: 51.1 | BC8: 7.7 | BD8: 13.5 | BL8: Samsung Electronics Company Limited | Taiwan Semiconductor Manufacturing Company Limited | SK Hynix Incorporated | WinWay Technology Company Limited | HD Hyundai Electric Company Limited | BM8: 18.6 | BN8: Very High | BO8: Equity Asia Pacific Asia | BQ8: 0.4827 | BR8: 2026-06-04 | BS8: 0.4734 | BT8: -1.93 | BU8: 11
A9: PUBLIC ASIA ITTIKAL FUND | B9: PAIF | C9: Shariah | D9: Equity | E9: Capital Growth | F9: 5 | G9: Incidental | H9: 5815.79 | I9: 22.08.2006 | J9: Qualified | K9: 100 | L9: 5/5 | M9: Qualified (WA: +13.70%) — YTD✔ 1Y✔ 3Y✔ 5Y✔ 10Y✔ | N9: 13.7 | O9: 42.6 | P9: 23.97 | Q9: 18.63 | R9: 101.66 | S9: 53.9 | T9: 47.76 | U9: 27.66 | V9: 17.23 | W9: 10.43 | X9: 7.64 | Y9: 3.7 | Z9: 3.94 | AA9: 11.37 | AB9: 8.42 | AC9: 2.95 | AD9: =IF(OR(Q9="",BM9="",BM9=0),"",Q9/BM9) | AE9: =IF(OR(T9="",BM9="",BM9=0),"",T9/BM9) | AF9: =IF(OR(W9="",BM9="",BM9=0),"",W9/BM9) | AG9: =IF(OR(Z9="",BM9="",BM9=0),"",Z9/BM9) | AH9: =IF(OR(AC9="",BM9="",BM9=0),"",AC9/BM9) | AJ9: 94.5 | AL9: 5.5 | AO9: 3.7 | AP9: 36.5 | AQ9: 37.6 | AR9: 10.7 | AU9: 6 | BA9: 30.6 | BB9: 50.9 | BD9: 13 | BL9: SK Hynix Incorporated | Samsung Electronics Company Limited | Taiwan Semiconductor Manufacturing Company Limited | Delta Electronics Incorporated | HD Hyundai Electric Company Limited | BM9: 21.6 | BN9: Very High | BO9: Equity Asia Pacific Asia | BP9: ThebenchmarkforPAIFisacompositeof30%KualaLumpurSyariahIndex(prior to 1 November 2007), 30% FTSE Bursa Malaysia EMAS Shariah Index (1 November 2007 to 29 April 2011), 30% FTSE Bursa Malaysia Hijrah Shariah Index (30April2011to29April2013),15%FTSEBursaMalaysiaHijrahShariahIndex (w.e.f. 30 April 2013), 15% customised indexbyS&P Dow Jones Indices, LLC based on top 20 constituents bymarket capitalisation of the S&P BMIShariah JapanIndex(w.e.f.30April2013)and70%DowJonesIslamicMarketAsiaEx- JapanIndexSM(priorto1January2009),70%S&PShariahBMIAsiaEx-Japan Index (w.e.f. 1 January 2009). UnderlyingindexdataaresourcedfromS&PDowJonesIndices,LLCandLipper and expressed in Ringgit terms. | BQ9: 0.865 | BR9: 2026-06-04 | BS9: 0.8362 | BT9: -3.33 | BU9: 11
A10: PUBLIC ISLAMIC GLOBAL SUSTAINABLE GROWTH FUND | B10: PISGSGF | C10: Shariah | D10: Equity | E10: Capital Growth | F10: 5 | G10: Incidental | H10: 761.58 | I10: 20.02.2024 | J10: Qualified | K10: 100 | L10: 2/2 | M10: Qualified (WA: +12.62%) — YTD✔ 1Y✔ | N10: 12.62 | O10: 7.02 | P10: 3.84 | Q10: 3.18 | R10: 38.2 | S10: 22.43 | T10: 15.77 | AD10: =IF(OR(Q10="",BM10="",BM10=0),"",Q10/BM10) | AE10: =IF(OR(T10="",BM10="",BM10=0),"",T10/BM10) | AF10: =IF(OR(W10="",BM10="",BM10=0),"",W10/BM10) | AG10: =IF(OR(Z10="",BM10="",BM10=0),"",Z10/BM10) | AH10: =IF(OR(AC10="",BM10="",BM10=0),"",AC10/BM10) | AI10: 3.3 | AJ10: 87.4 | AL10: 9.3 | AO10: 63.5 | AP10: 10.1 | AQ10: 2.6 | AU10: 3.9 | AW10: 6.4 | BB10: 53.4 | BC10: 4.6 | BD10: 25.8 | BE10: 5.4 | BF10: 1.5 | BL10: Alphabet Incorporated - Class A | Taiwan Semiconductor Manufacturing Company Limited | Apple Incorporated | Broadcom Incorporated | Microsoft Corporation | BP10: The benchmark for PISGSGF is a composite of 90% S&P Global 1200 ESG Shariah Index and 10% 3-Month Islamic Interbank Money Market (IIMM) rate. UnderlyingindexdataaresourcedfromS&PDowJonesIndices,LLCandBank Negara Malaysia and expressed in Ringgit terms. | BQ10: 0.3597 | BR10: 2026-06-03 | BS10: 0.346 | BT10: -3.81 | BU10: 12
A11: PB GREATER CHINA A-SHARES FUND | B11: PBGCASF | C11: Conventional | D11: Equity | E11: Capital Growth | F11: 5 | G11: Incidental | H11: 520.93 | I11: 10.03.2020 | J11: Qualified | K11: 100 | L11: 4/4 | M11: Qualified (WA: +11.01%) — YTD✔ 1Y✔ 3Y✔ 5Y✔ | N11: 11.01 | O11: 7.6 | P11: 4.56 | Q11: 3.04 | R11: 59.99 | S11: 19.36 | T11: 40.63 | U11: 15.56 | V11: 8.83 | W11: 6.73 | X11: 2.16 | Y11: 0.49 | Z11: 1.67 | AD11: =IF(OR(Q11="",BM11="",BM11=0),"",Q11/BM11) | AE11: =IF(OR(T11="",BM11="",BM11=0),"",T11/BM11) | AF11: =IF(OR(W11="",BM11="",BM11=0),"",W11/BM11) | AG11: =IF(OR(Z11="",BM11="",BM11=0),"",Z11/BM11) | AH11: =IF(OR(AC11="",BM11="",BM11=0),"",AC11/BM11) | AJ11: 92.6 | AL11: 7.4 | AO11: 2.6 | AP11: 26.2 | AU11: 63.8 | BA11: 8.2 | BB11: 45.6 | BD11: 17.9 | BE11: 8.8 | BI11: 4.5 | BL11: Taiwan Semiconductor Manufacturing Company Limited | Zhongji Innolight Company Limited - A Shares (HKS) | Hygon Information Technology Company Limited - A Shares (HKS) | Cambricon Technologies Corporation Limited - A Shares (HKS) | Alchip Technologies Limited | BM11: 20 | BN11: Very High | BO11: Equity Greater China Greater China | BP11: ThebenchmarkforPBGCASFisacompositeof50%S&PChinaA50Index,25% Hang Seng China Enterprises Index(HSCEI), 15% S&P Taiwan LargeCap Index and 10% 3-Month Kuala Lumpur Interbank Offered Rate (KLIBOR). UnderlyingindexdataaresourcedfromLipper,S&PDowJonesIndices,LLCand Bank Negara Malaysia and expressed in Ringgit terms. | BQ11: 0.4192 | BR11: 2026-06-03 | BS11: 0.4015 | BT11: -4.22 | BU11: 12
A12: PUBLIC ISLAMIC SELECT TREASURES FUND | B12: PISTF | C12: Shariah | D12: Equity | E12: Capital Growth | F12: 5 | G12: Incidental | H12: 1363.56 | I12: 26.02.2008 | J12: Qualified | K12: 100 | L12: 5/5 | M12: Qualified (WA: +10.99%) — YTD✔ 1Y✔ 3Y✔ 5Y✔ 10Y✔ | N12: 10.99 | O12: 14.88 | P12: 3.4 | Q12: 11.48 | R12: 32.33 | S12: 7.08 | T12: 25.25 | U12: 12.9 | V12: 2.71 | W12: 10.19 | X12: 4.49 | Y12: -2.5 | Z12: 6.99 | AA12: 6.45 | AB12: 1.07 | AC12: 5.38 | AD12: =IF(OR(Q12="",BM12="",BM12=0),"",Q12/BM12) | AE12: =IF(OR(T12="",BM12="",BM12=0),"",T12/BM12) | AF12: =IF(OR(W12="",BM12="",BM12=0),"",W12/BM12) | AG12: =IF(OR(Z12="",BM12="",BM12=0),"",Z12/BM12) | AH12: =IF(OR(AC12="",BM12="",BM12=0),"",AC12/BM12) | AI12: 75.2 | AJ12: 20.4 | AL12: 4.4 | AO12: 5.4 | AP12: 9.2 | AQ12: 2.6 | AR12: 3.2 | BA12: 40 | BB12: 6.7 | BC12: 15.6 | BD12: 7.8 | BF12: 20.7 | BL12: KPJ Healthcare Berhad | TIME dotCom Berhad | Frontken Corporation Berhad | Vitrox Corporation Berhad | Kelington Group Berhad | BM12: 9.2 | BN12: Moderate | BO12: Equity Malaysia Domestic | BQ12: 0.5474 | BR12: 2026-05-29 | BS12: 0.5439 | BT12: -0.64 | BU12: 17
A13: PB GLOBAL TECHNOLOGY & HEALTHCARE FUND | B13: PBGTHF | C13: Conventional | D13: Equity | E13: Capital Growth | F13: 5 | G13: Incidental | H13: 482.66 | I13: 09.05.2019 | J13: Qualified | K13: 100 | L13: 4/4 | M13: Qualified (WA: +9.74%) — YTD✔ 1Y✔ 3Y✔ 5Y✔ | N13: 9.74 | O13: 11.48 | P13: 1.58 | Q13: 9.9 | R13: 40.43 | S13: 19.19 | T13: 21.24 | U13: 24.21 | V13: 13.49 | W13: 10.72 | X13: 11.93 | Y13: 10.68 | Z13: 1.25 | AD13: =IF(OR(Q13="",BM13="",BM13=0),"",Q13/BM13) | AE13: =IF(OR(T13="",BM13="",BM13=0),"",T13/BM13) | AF13: =IF(OR(W13="",BM13="",BM13=0),"",W13/BM13) | AG13: =IF(OR(Z13="",BM13="",BM13=0),"",Z13/BM13) | AH13: =IF(OR(AC13="",BM13="",BM13=0),"",AC13/BM13) | AJ13: 93.4 | AL13: 6.6 | AO13: 49.4 | AP13: 17.2 | AQ13: 15.8 | AU13: 4.6 | AW13: 4.6 | BA13: 12.4 | BB13: 54.7 | BD13: 15.5 | BE13: 1.9 | BK13: 8.9 | BL13: Advanced Micro Devices Incorporated | Apple Incorporated | Taiwan Semiconductor Manufacturing Company Limited | HD Hyundai Electric Company Limited | Microsoft Corporation | BM13: 16.1 | BN13: Very High | BO13: Equity Global Global | BP13: ThebenchmarkforPBGTHFisacompositeof50%S&PGlobal1200Information Technology Index, 40% S&P Global 1200 Health Care Index and 10% 1-Month Kuala Lumpur Interbank Offered Rate (KLIBOR). Underlying index data are sourced from Lipper and Bank Negara Malaysia and expressed in Ringgit terms. | BQ13: 0.7637 | BR13: 2026-06-04 | BS13: 0.7398 | BT13: -3.13 | BU13: 11
A14: PUBLIC ISLAMIC OPTIMAL EQUITY FUND | B14: PIOEF | C14: Shariah | D14: Equity | E14: Capital Growth | F14: 5 | G14: Incidental | H14: 57.96 | I14: 26.07.2016 | J14: Qualified | K14: 75 | L14: 3/4 | M14: Qualified (WA: +9.36%) — YTD✔ 1Y✔ 3Y✔ 5Y✘ | N14: 9.36 | O14: 37.02 | P14: 17.86 | Q14: 19.16 | R14: 68.53 | S14: 39.51 | T14: 29.02 | U14: 21.55 | V14: 14.42 | W14: 7.13 | X14: 2.12 | Y14: 2.95 | Z14: -0.83 | AD14: =IF(OR(Q14="",BM14="",BM14=0),"",Q14/BM14) | AE14: =IF(OR(T14="",BM14="",BM14=0),"",T14/BM14) | AF14: =IF(OR(W14="",BM14="",BM14=0),"",W14/BM14) | AG14: =IF(OR(Z14="",BM14="",BM14=0),"",Z14/BM14) | AH14: =IF(OR(AC14="",BM14="",BM14=0),"",AC14/BM14) | AJ14: 85.9 | AL14: 14.1 | AO14: 7.9 | AP14: 49.4 | AQ14: 17 | AU14: 11.6 | BA14: 27.8 | BB14: 43.6 | BD14: 6.8 | BE14: 7.7 | BL14: Unimicron Technology Corporation | Taiwan Semiconductor Manufacturing Company Limited | Alibaba Group Holding Limited - W | Alchip Technologies Limited | HD Hyundai Electric Company Limited | BM14: 18 | BN14: Very High | BO14: Equity Asia Pacific Asia | BQ14: 0.5798 | BR14: 2026-06-04 | BS14: 0.5596 | BT14: -3.48 | BU14: 11
A15: PB ISLAMIC ASIA STRATEGIC SECTOR FUND | B15: PBIASSF | C15: Conventional | D15: Equity | E15: Capital Growth | F15: 5 | G15: Incidental | H15: 135.58 | I15: 06.09.2007 | J15: Qualified | K15: 100 | L15: 5/5 | M15: Qualified (WA: +9.28%) — YTD✔ 1Y✔ 3Y✔ 5Y✔ 10Y✔ | N15: 9.28 | O15: 43.35 | P15: 27.13 | Q15: 16.22 | R15: 96.3 | S15: 61.51 | T15: 34.79 | U15: 25.05 | V15: 18.79 | W15: 6.26 | X15: 5.87 | Y15: 4.1 | Z15: 1.77 | AA15: 11.36 | AB15: 9.33 | AC15: 2.03 | AD15: =IF(OR(Q15="",BM15="",BM15=0),"",Q15/BM15) | AE15: =IF(OR(T15="",BM15="",BM15=0),"",T15/BM15) | AF15: =IF(OR(W15="",BM15="",BM15=0),"",W15/BM15) | AG15: =IF(OR(Z15="",BM15="",BM15=0),"",Z15/BM15) | AH15: =IF(OR(AC15="",BM15="",BM15=0),"",AC15/BM15) | AJ15: 84.8 | AL15: 15.2 | AP15: 46.8 | AQ15: 26.7 | AR15: 2 | AU15: 9.3 | BA15: 29.6 | BB15: 42.3 | BD15: 12.9 | BL15: Delta Electronics Incorporated | SK Hynix Incorporated | Samsung Electronics Company Limited | Taiwan Semiconductor Manufacturing Company Limited | HD Hyundai Electric Company Limited | BM15: 20.8 | BN15: Very High | BO15: Equity Asia Pacific Asia | BP15: ThebenchmarkforPBIASSFisacompositeof90%DowJonesIslamicMarketAsia Ex-JapanIndexSM(priorto1January2009),90%S&PShariahBMIAsiaEx-Japan Index (w.e.f. 1 January 2009) and 10% 3-Month Islamic Interbank MoneyMarket (IIMM) rate. Underlying indexdata are sourced from S&P Dow Jones Indices, LLC and Bank Negara Malaysia and expressed in Ringgit terms. | BQ15: 0.7042 | BR15: 2026-06-04 | BS15: 0.6803 | BT15: -3.39 | BU15: 11
A16: PUBLIC e-ASIA EVOLVING GROWTH FUND | B16: PeAEVGF | C16: Conventional | D16: Equity | E16: Capital Growth | F16: 5 | G16: Incidental | H16: 782.73 | I16: 30.11.2021 | J16: Qualified | K16: 100 | L16: 3/3 | M16: Qualified (WA: +7.87%) — YTD✔ 1Y✔ 3Y✔ | N16: 7.87 | O16: 24.13 | P16: 13.7 | Q16: 10.43 | R16: 60.52 | S16: 42.63 | T16: 17.89 | U16: 22.21 | V16: 18.42 | W16: 3.79 | AD16: =IF(OR(Q16="",BM16="",BM16=0),"",Q16/BM16) | AE16: =IF(OR(T16="",BM16="",BM16=0),"",T16/BM16) | AF16: =IF(OR(W16="",BM16="",BM16=0),"",W16/BM16) | AG16: =IF(OR(Z16="",BM16="",BM16=0),"",Z16/BM16) | AH16: =IF(OR(AC16="",BM16="",BM16=0),"",AC16/BM16) | AI16: 1 | AJ16: 95.6 | AL16: 3.4 | AO16: 16.5 | AP16: 24.9 | AQ16: 23.5 | AT16: 1.3 | AU16: 29.4 | BA16: 18 | BB16: 43.2 | BC16: 1 | BD16: 31.7 | BE16: 2.7 | BL16: Taiwan Semiconductor Manufacturing Company Limited | SK Hynix Incorporated | Unimicron Technology Corporation | Tencent Holdings Limited | Alibaba Group Holding Limited - W | BM16: 19.7 | BN16: Very High | BO16: Equity Asia Pacific ex- Asia | BP16: ThebenchmarkforPeAEVGFisacompositeof90%customisedindexbyS&PDow JonesIndices,LLCbasedonthetop30constituentsoftheS&PBMIAsiaEx-Japan Index and 10% 3-Month Kuala Lumpur Interbank Offered Rate (KLIBOR). Underlying indexdata are sourced from S&P Dow Jones Indices, LLC and Bank Negara Malaysia and expressed in Ringgit terms. | BQ16: 0.4341 | BR16: 2026-06-04 | BS16: 0.422 | BT16: -2.79 | BU16: 11
A17: PUBLIC SMALLCAP FUND | B17: P SmallCap | C17: Conventional | D17: Equity | E17: Capital Growth | F17: 5 | G17: Incidental | H17: 1424.31 | I17: 13.06.2000 | J17: Qualified | K17: 100 | L17: 5/5 | M17: Qualified (WA: +7.86%) — YTD✔ 1Y✔ 3Y✔ 5Y✔ 10Y✔ | N17: 7.86 | O17: 3.42 | P17: -1.01 | Q17: 4.43 | R17: 18.7 | S17: 1.82 | T17: 16.88 | U17: 7.48 | V17: 0.25 | W17: 7.23 | X17: 3.79 | Y17: -1.91 | Z17: 5.7 | AA17: 5.41 | AB17: 0.12 | AC17: 5.29 | AD17: =IF(OR(Q17="",BM17="",BM17=0),"",Q17/BM17) | AE17: =IF(OR(T17="",BM17="",BM17=0),"",T17/BM17) | AF17: =IF(OR(W17="",BM17="",BM17=0),"",W17/BM17) | AG17: =IF(OR(Z17="",BM17="",BM17=0),"",Z17/BM17) | AH17: =IF(OR(AC17="",BM17="",BM17=0),"",AC17/BM17) | AI17: 76 | AJ17: 17.6 | AL17: 6.4 | AO17: 14.1 | AR17: 3.5 | BA17: 23 | BC17: 33.7 | BD17: 20.9 | BF17: 7.2 | BK17: 6.6 | BL17: TIME dotCom Berhad | IGB Real Estate Investment Trust | Malaysian Pacific Industries Berhad | Alphabet Incorporated - Class A | Hong Leong Industries Berhad | BM17: 8.9 | BN17: Moderate | BO17: Equity Malaysia Domestic 30% of the fund’s NAV | BQ17: 1.1808 | BR17: 2026-05-14 | BS17: 1.1432 | BT17: -3.18 | BU17: 32
A18: PUBLIC STRATEGIC SMALLCAP FUND | B18: PSSCF | C18: Conventional | D18: Equity | E18: Capital Growth | F18: 5 | G18: Incidental | H18: 448.96 | I18: 20.03.2012 | J18: Qualified | K18: 100 | L18: 5/5 | M18: Qualified (WA: +7.54%) — YTD✔ 1Y✔ 3Y✔ 5Y✔ 10Y✔ | N18: 7.54 | O18: 1.35 | P18: -1.01 | Q18: 2.36 | R18: 19.52 | S18: 1.82 | T18: 17.7 | U18: 7.99 | V18: 0.25 | W18: 7.74 | X18: 2.44 | Y18: -1.91 | Z18: 4.35 | AA18: 4.04 | AB18: 0.12 | AC18: 3.92 | AD18: =IF(OR(Q18="",BM18="",BM18=0),"",Q18/BM18) | AE18: =IF(OR(T18="",BM18="",BM18=0),"",T18/BM18) | AF18: =IF(OR(W18="",BM18="",BM18=0),"",W18/BM18) | AG18: =IF(OR(Z18="",BM18="",BM18=0),"",Z18/BM18) | AH18: =IF(OR(AC18="",BM18="",BM18=0),"",AC18/BM18) | AI18: 77.1 | AJ18: 18.9 | AL18: 4 | AO18: 15.3 | AR18: 3.6 | BA18: 40.3 | BC18: 14.2 | BD18: 15.9 | BF18: 13.7 | BK18: 6.3 | BL18: Kelington Group Berhad | Spritzer Berhad | Alphabet Incorporated - Class A | Malaysian Pacific Industries Berhad | SAM Engineering & Equipment (M) Berhad | BM18: 12.8 | BN18: High | BO18: Equity Malaysia Domestic 30% of the fund’s NAV | BP18: Index data are sourced from Lipper. | BQ18: 0.4893 | BR18: 2024-05-23 | BS18: 0.4739 | BT18: -3.15 | BU18: 753
A19: PUBLIC OPTIMAL EQUITY FUND | B19: POEF | C19: Conventional | D19: Equity | E19: Capital Growth | F19: 5 | G19: Incidental | H19: 29.69 | I19: 26.07.2016 | J19: Qualified | K19: 75 | L19: 3/4 | M19: Qualified (WA: +7.35%) — YTD✔ 1Y✔ 3Y✔ 5Y✘ | N19: 7.35 | O19: 26.63 | P19: 8.72 | Q19: 17.91 | R19: 51.86 | S19: 28.07 | T19: 23.79 | U19: 18.48 | V19: 13.36 | W19: 5.12 | X19: 1.78 | Y19: 2.84 | Z19: -1.06 | AD19: =IF(OR(Q19="",BM19="",BM19=0),"",Q19/BM19) | AE19: =IF(OR(T19="",BM19="",BM19=0),"",T19/BM19) | AF19: =IF(OR(W19="",BM19="",BM19=0),"",W19/BM19) | AG19: =IF(OR(Z19="",BM19="",BM19=0),"",Z19/BM19) | AH19: =IF(OR(AC19="",BM19="",BM19=0),"",AC19/BM19) | AJ19: 94.7 | AL19: 5.3 | AO19: 8.3 | AP19: 44.8 | AQ19: 26.7 | AU19: 14.9 | BA19: 23 | BB19: 50.5 | BD19: 19.1 | BE19: 2.1 | BL19: SK Hynix Incorporated | Samsung Electronics Company Limited | Taiwan Semiconductor Manufacturing Company Limited | Tencent Holdings Limited | Advanced Micro Devices Incorporated | BM19: 19.3 | BN19: Very High | BO19: Equity Asia Pacific Asia | BQ19: 0.4587 | BR19: 2026-06-04 | BS19: 0.4367 | BT19: -4.8 | BU19: 11
A20: PUBLIC ISLAMIC EMERGING OPPORTUNITIES FUND | B20: PIEMOF | C20: Shariah | D20: Equity | E20: Capital Growth | F20: 5 | G20: Incidental | H20: 101.17 | I20: 30.03.2016 | J20: Qualified | K20: 100 | L20: 5/5 | M20: Qualified (WA: +6.62%) — YTD✔ 1Y✔ 3Y✔ 5Y✔ 10Y✔ | N20: 6.62 | O20: 8.67 | P20: 3.19 | Q20: 5.48 | R20: 20.26 | S20: 6.76 | T20: 13.5 | U20: 9.37 | V20: 2.88 | W20: 6.49 | X20: 2.56 | Y20: -1.86 | Z20: 4.42 | AA20: 5.54 | AB20: 1.39 | AC20: 4.15 | AD20: =IF(OR(Q20="",BM20="",BM20=0),"",Q20/BM20) | AE20: =IF(OR(T20="",BM20="",BM20=0),"",T20/BM20) | AF20: =IF(OR(W20="",BM20="",BM20=0),"",W20/BM20) | AG20: =IF(OR(Z20="",BM20="",BM20=0),"",Z20/BM20) | AH20: =IF(OR(AC20="",BM20="",BM20=0),"",AC20/BM20) | AI20: 74.2 | AJ20: 21.6 | AL20: 4.2 | AO20: 7.9 | AP20: 6.1 | AQ20: 3.1 | AR20: 4.5 | BA20: 34.6 | BC20: 13.9 | BF20: 21.5 | BH20: 8.7 | BK20: 5.1 | BL20: Gas Malaysia Berhad | Spritzer Berhad | Vitrox Corporation Berhad | Kinik Company | KPJ Healthcare Berhad | BM20: 10 | BN20: Moderate | BO20: Equity Malaysia Domestic | BQ20: 0.4221 | BR20: 2026-05-29 | BS20: 0.4192 | BT20: -0.69 | BU20: 17
A21: PUBLIC ITTIKAL SEQUEL FUND | B21: PITSEQ | C21: Shariah | D21: Equity | E21: Capital Growth | F21: 4 | G21: Incidental | H21: 4541.6 | I21: 11.10.2011 | J21: Qualified | K21: 80 | L21: 4/5 | M21: Qualified (WA: +6.16%) — YTD✘ 1Y✔ 3Y✔ 5Y✔ 10Y✔ | N21: 6.16 | O21: 4.24 | P21: 5.14 | Q21: -0.9 | R21: 15.15 | S21: 12.81 | T21: 2.34 | U21: 13.88 | V21: 5.79 | W21: 8.09 | X21: 6.25 | Y21: -0.85 | Z21: 7.1 | AA21: 6.01 | AB21: 0.41 | AC21: 5.6 | AD21: =IF(OR(Q21="",BM21="",BM21=0),"",Q21/BM21) | AE21: =IF(OR(T21="",BM21="",BM21=0),"",T21/BM21) | AF21: =IF(OR(W21="",BM21="",BM21=0),"",W21/BM21) | AG21: =IF(OR(Z21="",BM21="",BM21=0),"",Z21/BM21) | AH21: =IF(OR(AC21="",BM21="",BM21=0),"",AC21/BM21) | AI21: 73.4 | AJ21: 22.7 | AL21: 3.9 | AO21: 18.2 | AP21: 4.5 | BB21: 13.7 | BC21: 15.4 | BD21: 19.7 | BF21: 16.6 | BG21: 9.1 | BL21: Tenaga Nasional Berhad | Telekom Malaysia Berhad | Sunway Berhad | Gamuda Berhad | Press Metal Aluminium Holdings Berhad | BM21: 7.5 | BN21: Low | BO21: Equity Malaysia Domestic | BP21: Index data are sourced from Lipper. 2022 1.00 30.11.22 3.4 Note: Distribution yield simply measures the level of distributions and is not a measure of fund performance. | BQ21: 0.4597 | BR21: 2026-05-12 | BS21: 0.4541 | BT21: -1.22 | BU21: 34
A22: PUBLIC ISLAMIC ASIA DIVIDEND FUND | B22: PIADF | C22: Shariah | D22: Equity | E22: Income | F22: 5 | G22: Annual | H22: 1765.59 | I22: 03.04.2007 | J22: Qualified | K22: 100 | L22: 5/5 | M22: Qualified (WA: +5.90%) — YTD✔ 1Y✔ 3Y✔ 5Y✔ 10Y✔ | N22: 5.9 | O22: 31.7 | P22: 22.05 | Q22: 9.65 | R22: 62.66 | S22: 49.56 | T22: 13.1 | U22: 22.95 | V22: 16.19 | W22: 6.76 | X22: 5.19 | Y22: 3.53 | Z22: 1.66 | AA22: 9.75 | AB22: 7.54 | AC22: 2.21 | AD22: =IF(OR(Q22="",BM22="",BM22=0),"",Q22/BM22) | AE22: =IF(OR(T22="",BM22="",BM22=0),"",T22/BM22) | AF22: =IF(OR(W22="",BM22="",BM22=0),"",W22/BM22) | AG22: =IF(OR(Z22="",BM22="",BM22=0),"",Z22/BM22) | AH22: =IF(OR(AC22="",BM22="",BM22=0),"",AC22/BM22) | AI22: 1.7 | AJ22: 90.9 | AL22: 7.4 | AO22: 5.6 | AP22: 31.1 | AQ22: 34 | AU22: 13 | AY22: 3.5 | BA22: 29.7 | BB22: 30.1 | BD22: 25.9 | BE22: 3.3 | BI22: 2.2 | BL22: Samsung Electronics Company Limited | SK Hynix Incorporated | Taiwan Semiconductor Manufacturing Company Limited | Hanwha Aerospace Company Limited | Elite Material Company Limited | BM22: 16.1 | BN22: Very High | BO22: Equity Asia Pacific Asia | BQ22: 0.6678 | BR22: 2026-06-04 | BS22: 0.6493 | BT22: -2.77 | BU22: 11
A23: PUBLIC GREATER CHINA FUND | B23: PGCF | C23: Conventional | D23: Equity | E23: Capital Growth | F23: 5 | G23: Incidental | H23: 384.55 | I23: 26.10.2017 | J23: Qualified | K23: 100 | L23: 4/4 | M23: Qualified (WA: +5.90%) — YTD✔ 1Y✔ 3Y✔ 5Y✔ | N23: 5.9 | O23: 14.71 | P23: 7.04 | Q23: 7.67 | R23: 37.36 | S23: 26.81 | T23: 10.55 | U23: 18.18 | V23: 12.44 | W23: 5.74 | X23: 2.84 | Y23: -0.18 | Z23: 3.02 | AD23: =IF(OR(Q23="",BM23="",BM23=0),"",Q23/BM23) | AE23: =IF(OR(T23="",BM23="",BM23=0),"",T23/BM23) | AF23: =IF(OR(W23="",BM23="",BM23=0),"",W23/BM23) | AG23: =IF(OR(Z23="",BM23="",BM23=0),"",Z23/BM23) | AH23: =IF(OR(AC23="",BM23="",BM23=0),"",AC23/BM23) | AJ23: 93.5 | AL23: 6.5 | AO23: 13.7 | AP23: 45.7 | AT23: 1.4 | AU23: 1.3 | BA23: 19.7 | BB23: 32.1 | BC23: 3.4 | BD23: 30.2 | BE23: 8.1 | BL23: Taiwan Semiconductor Manufacturing Company Limited | Alibaba Group Holding Limited - W | Delta Electronics Incorporated | Tencent Holdings Limited | ASPEED Technology Incorporated | BM23: 15.6 | BN23: Very High | BO23: Greater China | BP23: MSCI Golden Dragon Index (prior to 30 April 2021), S&P Greater China LargeMidCap Index (30 April 2021 to 1 January 2025), S&P Greater China LargeMidCap 8% Capped Index (w.e.f. 2 January 2025). UnderlyingIndexdataaresourcedfromS&PDowJonesIndices,LLCandLipper and expressed in Ringgit terms. | BQ23: 0.4085 | BR23: 2026-06-03 | BS23: 0.3901 | BT23: -4.5 | BU23: 12
A24: PUBLIC ISLAMIC SAVINGS FUND | B24: PISVF | C24: Shariah | D24: Equity | E24: Income | F24: 4 | G24: Semi-Annual | H24: 510.62 | I24: 15.12.2011 | J24: Qualified | K24: 100 | L24: 5/5 | M24: Qualified (WA: +5.89%) — YTD✔ 1Y✔ 3Y✔ 5Y✔ 10Y✔ | N24: 5.89 | O24: 7.69 | P24: 4.74 | Q24: 2.95 | R24: 25.36 | S24: 11.86 | T24: 13.5 | U24: 10.99 | V24: 5.62 | W24: 5.37 | X24: 3.14 | Y24: -0.4 | Z24: 3.54 | AA24: 5.3 | AB24: 0.75 | AC24: 4.55 | AD24: =IF(OR(Q24="",BM24="",BM24=0),"",Q24/BM24) | AE24: =IF(OR(T24="",BM24="",BM24=0),"",T24/BM24) | AF24: =IF(OR(W24="",BM24="",BM24=0),"",W24/BM24) | AG24: =IF(OR(Z24="",BM24="",BM24=0),"",Z24/BM24) | AH24: =IF(OR(AC24="",BM24="",BM24=0),"",AC24/BM24) | AI24: 75.7 | AJ24: 21.6 | AL24: 2.7 | AO24: 10.6 | AP24: 3.8 | AQ24: 7.2 | BA24: 26.1 | BB24: 12.1 | BC24: 12.1 | BD24: 13.1 | BF24: 10.1 | BL24: Press Metal Aluminium Holdings Berhad | Tenaga Nasional Berhad | HD Hyundai Electric Company Limited | Telekom Malaysia Berhad | IHH Healthcare Berhad | BM24: 9.5 | BN24: Moderate | BO24: Equity Malaysia Domestic | BQ24: 0.4381 | BR24: 2026-05-14 | BS24: 0.4286 | BT24: -2.17 | BU24: 32
A25: PB CHINA PACIFIC EQUITY FUND | B25: PBCPEF | C25: Conventional | D25: Equity | E25: Capital Growth | F25: 5 | G25: Incidental | H25: 229.83 | I25: 23.10.2007 | J25: Qualified | K25: 100 | L25: 5/5 | M25: Qualified (WA: +5.76%) — YTD✔ 1Y✔ 3Y✔ 5Y✔ 10Y✔ | N25: 5.76 | O25: 23.14 | P25: 9.66 | Q25: 13.48 | R25: 44.67 | S25: 32.09 | T25: 12.58 | U25: 17.11 | V25: 11.4 | W25: 5.71 | X25: 1.25 | Y25: -1.3 | Z25: 2.55 | AA25: 8.66 | AB25: 6.82 | AC25: 1.84 | AD25: =IF(OR(Q25="",BM25="",BM25=0),"",Q25/BM25) | AE25: =IF(OR(T25="",BM25="",BM25=0),"",T25/BM25) | AF25: =IF(OR(W25="",BM25="",BM25=0),"",W25/BM25) | AG25: =IF(OR(Z25="",BM25="",BM25=0),"",Z25/BM25) | AH25: =IF(OR(AC25="",BM25="",BM25=0),"",AC25/BM25) | AJ25: 95 | AL25: 5 | AO25: 4.8 | AP25: 47.3 | AQ25: 28.4 | AR25: 0.4 | AU25: 14.1 | BA25: 26.5 | BB25: 50 | BD25: 18 | BE25: 0.5 | BL25: SK Hynix Incorporated | Taiwan Semiconductor Manufacturing Company Limited | Samsung Electronics Company Limited | Tencent Holdings Limited | Delta Electronics Incorporated | BM25: 19.3 | BN25: Very High | BO25: Equity Asia Pacific Greater China | BP25: ThebenchmarkforPBCPEFisacompositeof70%HangSengChinaEnterprises Index (HSCEI) and 30% Hang Seng Index (HSI) (prior to 1 January 2009). MSCI Zhong Hua Index (1 January 2009 to 29 April 2015). 80%MSCIZhongHuaIndex(30April2015to29April2021),80%S&PChina& HongKongLargeMidCapIndex(30April 2021to28December2025),60%S&P China&HongKongLargeMidCapIndex(w.e.f.29December2025),10%KOSPI50 Index (30 April 2015 to 29 April 2016), 10% MSCI Korea Large Cap Index (30April2016to29April2021),10%S&PKoreaLargeCapIndex(30April2021to 28December2025),15%S&PKoreaLargeCapIndex(w.e.f.29December2025), 10% FTSE TWSE Taiwan50 Index(30 April 2015 to29 April 2016), 10% MSCI Taiwan Large Cap Index (30 April 2016 to 29 April 2021), 10% S&P Taiwan LargeCapIndex(30April2021to28December2025),15%S&PTaiwanLargeCap Index(w.e.f.29December2025)and10%3-MonthKualaLumpurInterbankOffered Rate (KLIBOR) (w.e.f. 29 December 2025). UnderlyingindexdataaresourcedfromS&PDowJonesIndices,LLC,Lipperand Bank Negara Malaysia and expressed in Ringgit terms. | BQ25: 0.5509 | BR25: 2026-06-04 | BS25: 0.5278 | BT25: -4.19 | BU25: 11
A26: PB SMALLCAP GROWTH FUND | B26: PBSCGF | C26: Conventional | D26: Equity | E26: Capital Growth | F26: 5 | G26: Incidental | H26: 123.09 | I26: 13.01.2016 | J26: Qualified | K26: 80 | L26: 4/5 | M26: Qualified (WA: +5.70%) — YTD✘ 1Y✔ 3Y✔ 5Y✔ 10Y✔ | N26: 5.7 | O26: -1.39 | P26: -0.78 | Q26: -0.61 | R26: 19.08 | S26: 2.02 | T26: 17.06 | U26: 5.06 | V26: 0.65 | W26: 4.41 | X26: 2.09 | Y26: -1.34 | Z26: 3.43 | AA26: 4.2 | AB26: 0.54 | AC26: 3.66 | AD26: =IF(OR(Q26="",BM26="",BM26=0),"",Q26/BM26) | AE26: =IF(OR(T26="",BM26="",BM26=0),"",T26/BM26) | AF26: =IF(OR(W26="",BM26="",BM26=0),"",W26/BM26) | AG26: =IF(OR(Z26="",BM26="",BM26=0),"",Z26/BM26) | AH26: =IF(OR(AC26="",BM26="",BM26=0),"",AC26/BM26) | AI26: 77.2 | AJ26: 17.2 | AL26: 5.6 | AO26: 12.6 | AR26: 4.6 | BA26: 44 | BC26: 7.4 | BD26: 9.2 | BF26: 23.5 | BK26: 7.6 | BL26: Spritzer Berhad | Malaysian Pacific Industries Berhad | UWC Berhad | MN Holdings Berhad | Southern Cable Group Berhad | BM26: 12.9 | BN26: High | BO26: Equity Malaysia Small & | BQ26: 0.3595 | BR26: 2024-06-14 | BS26: 0.3516 | BT26: -2.2 | BU26: 731
A27: PB ISLAMIC ASIA EQUITY FUND | B27: PBIAEF | C27: Conventional | D27: Equity | E27: Capital Growth | F27: 5 | G27: Incidental | H27: 139.65 | I27: 08.01.2007 | J27: Qualified | K27: 100 | L27: 5/5 | M27: Qualified (WA: +5.49%) — YTD✔ 1Y✔ 3Y✔ 5Y✔ 10Y✔ | N27: 5.49 | O27: 29.83 | P27: 25.06 | Q27: 4.77 | R27: 79.45 | S27: 56.89 | T27: 22.56 | U27: 22.33 | V27: 17.8 | W27: 4.53 | X27: 3.7 | Y27: 3.47 | Z27: 0.23 | AA27: 8.1 | AB27: 8.09 | AC27: 0.01 | AD27: =IF(OR(Q27="",BM27="",BM27=0),"",Q27/BM27) | AE27: =IF(OR(T27="",BM27="",BM27=0),"",T27/BM27) | AF27: =IF(OR(W27="",BM27="",BM27=0),"",W27/BM27) | AG27: =IF(OR(Z27="",BM27="",BM27=0),"",Z27/BM27) | AH27: =IF(OR(AC27="",BM27="",BM27=0),"",AC27/BM27) | AJ27: 83.4 | AL27: 16.6 | AP27: 33.2 | AQ27: 29.8 | AR27: 0.9 | AU27: 17.3 | AZ27: 2.2 | BA27: 15.8 | BB27: 43 | BD27: 24.6 | BL27: SK Hynix Incorporated | Taiwan Semiconductor Manufacturing Company Limited | Alibaba Group Holding Limited - W | Samsung Electronics Company Limited | Tencent Holdings Limited | BM27: 16.3 | BN27: Very High | BO27: Equity Asia Pacific Asia | BP27: The benchmark for PBIAEF is a composite of 20% Kuala Lumpur Syariah Index (prior to 1 November 2007), 20% FTSE Bursa Malaysia EMAS Shariah Index (1 November 2007 to 29 April 2011), 20% FTSE Bursa Malaysia Hijrah Shariah Index (w.e.f. 30 April 2011) and 80% Dow Jones Islamic Market Asia Ex-Japan IndexSM (prior to 1 January 2009), 80% S&P Shariah BMI Asia Ex-Japan Index (w.e.f. 1 January 2009). UnderlyingindexdataaresourcedfromS&PDowJonesIndices,LLCandLipper and expressed in Ringgit terms. | BQ27: 0.4907 | BR27: 2026-06-04 | BS27: 0.4773 | BT27: -2.73 | BU27: 11
A28: PUBLIC ISLAMIC OPPORTUNITIES FUND | B28: PIOF | C28: Shariah | D28: Equity | E28: Capital Growth | F28: 5 | G28: Incidental | H28: 1137.4 | I28: 28.06.2005 | J28: Qualified | K28: 100 | L28: 5/5 | M28: Qualified (WA: +5.43%) — YTD✔ 1Y✔ 3Y✔ 5Y✔ 10Y✔ | N28: 5.43 | O28: 8.56 | P28: -2.13 | Q28: 10.69 | R28: 13.5 | S28: 3 | T28: 10.5 | U28: 5.51 | V28: 0.98 | W28: 4.53 | X28: 0.43 | Y28: -1.87 | Z28: 2.3 | AA28: 6.28 | AB28: 0.04 | AC28: 6.24 | AD28: =IF(OR(Q28="",BM28="",BM28=0),"",Q28/BM28) | AE28: =IF(OR(T28="",BM28="",BM28=0),"",T28/BM28) | AF28: =IF(OR(W28="",BM28="",BM28=0),"",W28/BM28) | AG28: =IF(OR(Z28="",BM28="",BM28=0),"",Z28/BM28) | AH28: =IF(OR(AC28="",BM28="",BM28=0),"",AC28/BM28) | AI28: 76.3 | AJ28: 19.4 | AL28: 4.3 | AO28: 5.7 | AP28: 5.7 | AQ28: 8 | BA28: 42.9 | BB28: 16.1 | BC28: 11 | BE28: 6.7 | BF28: 11.2 | BL28: Kelington Group Berhad | Frontken Corporation Berhad | Taiwan Semiconductor Manufacturing Company Limited | UWC Berhad | HD Hyundai Electric Company Limited | BM28: 11.5 | BN28: High | BO28: Equity Malaysia Domestic | BP28: 2023 1.00 31.7.23 1.9 Kuala Lumpur Syariah Index (prior to 1 November 2007). Note: Distribution yield simply measures the level of distributions and is not FTSE Bursa Malaysia EMAS Shariah Index (1 November 2007 to 29 April 2013). a measure of fund performance. FTSE Bursa Malaysia Small Cap Shariah Index (w.e.f. 30 April 2013). Underlying index data are sourced from Lipper. | BQ28: 0.714 | BR28: 2021-11-19 | BS28: 0.6276 | BT28: -12.1 | BU28: 1669
A29: PUBLIC ITTIKAL FUND | B29: P ITTIKAL | C29: Shariah | D29: Equity | E29: Capital Growth | F29: 4 | G29: Incidental | H29: 3992.97 | I29: 10.04.1997 | J29: Qualified | K29: 80 | L29: 4/5 | M29: Qualified (WA: +5.40%) — YTD✘ 1Y✔ 3Y✔ 5Y✔ 10Y✔ | N29: 5.4 | O29: 4.47 | P29: 5.14 | Q29: -0.67 | R29: 21.24 | S29: 12.81 | T29: 8.43 | U29: 11.24 | V29: 5.79 | W29: 5.45 | X29: 4.98 | Y29: -0.85 | Z29: 5.83 | AA29: 3.98 | AB29: 0.41 | AC29: 3.57 | AD29: =IF(OR(Q29="",BM29="",BM29=0),"",Q29/BM29) | AE29: =IF(OR(T29="",BM29="",BM29=0),"",T29/BM29) | AF29: =IF(OR(W29="",BM29="",BM29=0),"",W29/BM29) | AG29: =IF(OR(Z29="",BM29="",BM29=0),"",Z29/BM29) | AH29: =IF(OR(AC29="",BM29="",BM29=0),"",AC29/BM29) | AI29: 74.7 | AJ29: 23.3 | AL29: 2 | AO29: 14.5 | AP29: 8.8 | BB29: 15.3 | BC29: 13.2 | BD29: 19.1 | BF29: 20.5 | BG29: 9.6 | BL29: Tenaga Nasional Berhad | IHH Healthcare Berhad | Telekom Malaysia Berhad | Sunway Berhad | Taiwan Semiconductor Manufacturing Company Limited | BM29: 8.6 | BN29: Moderate | BO29: Equity Malaysia Domestic | BP29: Kuala Lumpur Syariah Index (prior to 1 November 2007). FTSE Bursa Malaysia EMAS Shariah Index (w.e.f. 1 November 2007). | BQ29: 1.31 | BR29: 2000-02-24 | BS29: 1.0312 | BT29: -21.28 | BU29: 9608
A30: PUBLIC EMERGING OPPORTUNITIES FUND | B30: PEMOF | C30: Conventional | D30: Equity | E30: Capital Growth | F30: 5 | G30: Incidental | H30: 148.42 | I30: 30.03.2016 | J30: Qualified | K30: 100 | L30: 5/5 | M30: Qualified (WA: +5.40%) — YTD✔ 1Y✔ 3Y✔ 5Y✔ 10Y✔ | N30: 5.4 | O30: 9 | P30: 4.34 | Q30: 4.66 | R30: 23.41 | S30: 8.88 | T30: 14.53 | U30: 11.14 | V30: 6.55 | W30: 4.59 | X30: 2.76 | Y30: 1.66 | Z30: 1.1 | AA30: 8.36 | AB30: 2.54 | AC30: 5.82 | AD30: =IF(OR(Q30="",BM30="",BM30=0),"",Q30/BM30) | AE30: =IF(OR(T30="",BM30="",BM30=0),"",T30/BM30) | AF30: =IF(OR(W30="",BM30="",BM30=0),"",W30/BM30) | AG30: =IF(OR(Z30="",BM30="",BM30=0),"",Z30/BM30) | AH30: =IF(OR(AC30="",BM30="",BM30=0),"",AC30/BM30) | AI30: 76.1 | AJ30: 21.9 | AL30: 2 | AO30: 4.6 | AP30: 15 | AT30: 2.3 | BA30: 46.2 | BB30: 8 | BC30: 25.5 | BD30: 4.3 | BF30: 8.2 | BL30: Kelington Group Berhad | Hon.Precision Incorporated | Kinik Company | Sunway Real Estate Investment Trust | IGB Real Estate Investment Trust | BM30: 11.6 | BN30: High | BO30: Equity Malaysia Domestic 25% of the fund’s NAV | BP30: ThebenchmarkforPEMOFisacompositeof60%FTSEBursaMalaysiaMid70 Index, 30% FTSE Bursa Malaysia Small Cap Index and 10% 3-Month Kuala Lumpur Interbank Offered Rate (KLIBOR). Underlying index data are sourced from Lipper and Bank Negara Malaysia. | BQ30: 0.609 | BR30: 2026-05-29 | BS30: 0.5943 | BT30: -2.41 | BU30: 17
A31: PUBLIC e-ISLAMIC ASIA THEMATIC GROWTH FUND | B31: PeIATGF | C31: Shariah | D31: Equity | E31: Capital Growth | F31: 5 | G31: Incidental | H31: 538.28 | I31: 30.11.2021 | J31: Qualified | K31: 100 | L31: 3/3 | M31: Qualified (WA: +5.37%) — YTD✔ 1Y✔ 3Y✔ | N31: 5.37 | O31: 42.09 | P31: 32.08 | Q31: 10.01 | R31: 78.32 | S31: 72.28 | T31: 6.04 | U31: 26.7 | V31: 22.16 | W31: 4.54 | AD31: =IF(OR(Q31="",BM31="",BM31=0),"",Q31/BM31) | AE31: =IF(OR(T31="",BM31="",BM31=0),"",T31/BM31) | AF31: =IF(OR(W31="",BM31="",BM31=0),"",W31/BM31) | AG31: =IF(OR(Z31="",BM31="",BM31=0),"",Z31/BM31) | AH31: =IF(OR(AC31="",BM31="",BM31=0),"",AC31/BM31) | AJ31: 92.3 | AL31: 7.7 | AO31: 5.2 | AP31: 50 | AQ31: 27.9 | AU31: 9.2 | BA31: 33.3 | BB31: 45.9 | BD31: 13.1 | BL31: SK Hynix Incorporated | Samsung Electronics Company Limited | Delta Electronics Incorporated | Taiwan Semiconductor Manufacturing Company Limited | Alibaba Group Holding Limited - W | BM31: 19.7 | BN31: Very High | BO31: Equity Asia Pacific ex- Asia | BP31: ThebenchmarkforPeIATGFisacustomisedindexbyS&PDowJonesIndices,LLC basedonthetop100constituentsbymarketcapitalisationoftheS&PShariahBMI Asia Ex-Japan Index. Underlying index data are sourced from S&P Dow Jones Indices, LLC and expressed in Ringgit terms. | BQ31: 0.4862 | BR31: 2026-06-04 | BS31: 0.4636 | BT31: -4.65 | BU31: 11
A32: PB ISLAMIC SMALLCAP FUND | B32: PBISCF | C32: Conventional | D32: Equity | E32: Capital Growth | F32: 5 | G32: Incidental | H32: 114.01 | I32: 28.03.2017 | J32: Qualified | K32: 100 | L32: 4/4 | M32: Qualified (WA: +4.83%) — YTD✔ 1Y✔ 3Y✔ 5Y✔ | N32: 4.83 | O32: 0.8 | P32: -2.13 | Q32: 2.93 | R32: 13.89 | S32: 3 | T32: 10.89 | U32: 4.59 | V32: 0.98 | W32: 3.61 | X32: 1.67 | Y32: -1.87 | Z32: 3.54 | AD32: =IF(OR(Q32="",BM32="",BM32=0),"",Q32/BM32) | AE32: =IF(OR(T32="",BM32="",BM32=0),"",T32/BM32) | AF32: =IF(OR(W32="",BM32="",BM32=0),"",W32/BM32) | AG32: =IF(OR(Z32="",BM32="",BM32=0),"",Z32/BM32) | AH32: =IF(OR(AC32="",BM32="",BM32=0),"",AC32/BM32) | AI32: 75.5 | AJ32: 19.6 | AL32: 4.9 | AO32: 4.8 | AP32: 6.1 | AQ32: 6.3 | AR32: 2.4 | BA32: 54 | BB32: 8.1 | BC32: 6.2 | BF32: 17.3 | BK32: 3.8 | BL32: Kelington Group Berhad | Frontken Corporation Berhad | Spritzer Berhad | HD Hyundai Electric Company Limited | Taiwan Semiconductor Manufacturing Company Limited | BM32: 12.6 | BN32: High | BO32: Equity Malaysia Small & | BP32: Index data are sourced from Lipper. | BQ32: 0.4582 | BR32: 2022-01-04 | BS32: 0.3887 | BT32: -15.17 | BU32: 1623
A33: PUBLIC ISLAMIC TREASURES GROWTH FUND | B33: PITGF | C33: Shariah | D33: Equity | E33: Capital Growth | F33: 5 | G33: Incidental | H33: 278.85 | I33: 19.07.2011 | J33: Qualified | K33: 100 | L33: 5/5 | M33: Qualified (WA: +4.81%) — YTD✔ 1Y✔ 3Y✔ 5Y✔ 10Y✔ | N33: 4.81 | O33: 10.86 | P33: 3.19 | Q33: 7.67 | R33: 18.02 | S33: 6.76 | T33: 11.26 | U33: 7.3 | V33: 2.88 | W33: 4.42 | X33: 0.33 | Y33: -1.86 | Z33: 2.19 | AA33: 4.19 | AB33: 1.39 | AC33: 2.8 | AD33: =IF(OR(Q33="",BM33="",BM33=0),"",Q33/BM33) | AE33: =IF(OR(T33="",BM33="",BM33=0),"",T33/BM33) | AF33: =IF(OR(W33="",BM33="",BM33=0),"",W33/BM33) | AG33: =IF(OR(Z33="",BM33="",BM33=0),"",Z33/BM33) | AH33: =IF(OR(AC33="",BM33="",BM33=0),"",AC33/BM33) | AI33: 76 | AJ33: 18.5 | AL33: 5.5 | AO33: 7.8 | AP33: 6.1 | AR33: 4.6 | BA33: 35.1 | BC33: 11.9 | BD33: 8.3 | BF33: 18.1 | BK33: 7.7 | BL33: Vitrox Corporation Berhad | TIME dotCom Berhad | Malaysian Pacific Industries Berhad | QL Resources Berhad | Bursa Malaysia Berhad | BM33: 10.3 | BN33: High | BO33: Equity Malaysia Domestic | BP33: The benchmark for PITGF is a composite of 90% FTSE Bursa Malaysia EMAS Shariah Index (prior to 30 April 2013), 90% FTSE Bursa Malaysia Small Cap ShariahIndex(FBMSSC)(30April2013to29April2015),90%customisedindex byFTSEbasedontheconstituentswithmarketcapitalisationbelowRM6.0billion withintheFTSE BursaMalaysiaEMAS ShariahIndex(w.e.f. 30April 2015)and 10% 3-Month Islamic Interbank Money Market (IIMM) rate. Underlying index data are sourced from FTSE International Limited, Lipper and Bank Negara Malaysia. | BQ33: 0.437 | BR33: 2026-05-29 | BS33: 0.436 | BT33: -0.23 | BU33: 17
A34: PUBLIC e-ISLAMIC GROWTH FUND | B34: PeIGRF | C34: Shariah | D34: Equity | E34: Capital Growth | F34: 4 | G34: Incidental | H34: 65.65 | I34: 10.12.2021 | J34: Qualified | K34: 66.7 | L34: 2/3 | M34: Qualified (WA: +4.71%) — YTD✘ 1Y✔ 3Y✔ | N34: 4.71 | O34: 3.96 | P34: 4.74 | Q34: -0.78 | R34: 21.83 | S34: 11.86 | T34: 9.97 | U34: 9.04 | V34: 5.62 | W34: 3.42 | AD34: =IF(OR(Q34="",BM34="",BM34=0),"",Q34/BM34) | AE34: =IF(OR(T34="",BM34="",BM34=0),"",T34/BM34) | AF34: =IF(OR(W34="",BM34="",BM34=0),"",W34/BM34) | AG34: =IF(OR(Z34="",BM34="",BM34=0),"",Z34/BM34) | AH34: =IF(OR(AC34="",BM34="",BM34=0),"",AC34/BM34) | AI34: 77.8 | AJ34: 17.3 | AL34: 4.9 | AO34: 13.8 | AP34: 3.5 | BA34: 12.7 | BD34: 25.3 | BF34: 17 | BG34: 10.7 | BI34: 9.2 | BL34: Tenaga Nasional Berhad | Press Metal Aluminium Holdings Berhad | Telekom Malaysia Berhad | TIME dotCom Berhad | IHH Healthcare Berhad | BM34: 9.3 | BN34: Moderate | BO34: Equity Malaysia | BP34: Thebenchmark for PeIGRFis acomposite of90% FTSE Bursa MalaysiaEMAS Shariah Index and 10% 3-Month Islamic Interbank Money Market (IIMM) rate. Underlying index data are sourced from Lipper and Bank Negara Malaysia. | BQ34: 0.3082 | BR34: 2026-05-22 | BS34: 0.3029 | BT34: -1.72 | BU34: 24
A35: PB GROWTH SEQUEL FUND | B35: PBGSQF | C35: Conventional | D35: Equity | E35: Capital Growth | F35: 4 | G35: Incidental | H35: 63.12 | I35: 15.11.2011 | J35: Qualified | K35: 80 | L35: 4/5 | M35: Qualified (WA: +4.63%) — YTD✘ 1Y✔ 3Y✔ 5Y✔ 10Y✔ | N35: 4.63 | O35: 0.73 | P35: 2.49 | Q35: -1.76 | R35: 17.11 | S35: 11.8 | T35: 5.31 | U35: 12.53 | V35: 6.72 | W35: 5.81 | X35: 5.38 | Y35: 1.46 | Z35: 3.92 | AA35: 4.39 | AB35: 0.29 | AC35: 4.1 | AD35: =IF(OR(Q35="",BM35="",BM35=0),"",Q35/BM35) | AE35: =IF(OR(T35="",BM35="",BM35=0),"",T35/BM35) | AF35: =IF(OR(W35="",BM35="",BM35=0),"",W35/BM35) | AG35: =IF(OR(Z35="",BM35="",BM35=0),"",Z35/BM35) | AH35: =IF(OR(AC35="",BM35="",BM35=0),"",AC35/BM35) | AI35: 74.4 | AJ35: 22.8 | AL35: 2.8 | AO35: 15.9 | AP35: 6.4 | BA35: 27.7 | BB35: 10.3 | BC35: 23.8 | BD35: 19.2 | BF35: 8 | BL35: Public Bank Berhad | Sunway Berhad | QL Resources Berhad | Southern Cable Group Berhad | Alphabet Incorporated - Class A | BM35: 10.1 | BN35: Moderate | BO35: Equity Malaysia | BP35: Index data are sourced from Lipper. | BQ35: 0.3945 | BR35: 2026-06-03 | BS35: 0.3913 | BT35: -0.81 | BU35: 12
A36: PUBLIC INDUSTRY GROWTH FUND | B36: PINDGF | C36: Shariah | D36: Equity | E36: Capital Growth | F36: 4 | G36: Incidental | H36: 248.52 | I36: 18.11.1993 | J36: Qualified | K36: 100 | L36: 5/5 | M36: Qualified (WA: +4.44%) — YTD✔ 1Y✔ 3Y✔ 5Y✔ 10Y✔ | N36: 4.44 | O36: 5.94 | P36: 2.49 | Q36: 3.45 | R36: 18.27 | S36: 11.8 | T36: 6.47 | U36: 11.75 | V36: 6.72 | W36: 5.03 | X36: 3.55 | Y36: 1.46 | Z36: 2.09 | AA36: 5.35 | AB36: 0.29 | AC36: 5.06 | AD36: =IF(OR(Q36="",BM36="",BM36=0),"",Q36/BM36) | AE36: =IF(OR(T36="",BM36="",BM36=0),"",T36/BM36) | AF36: =IF(OR(W36="",BM36="",BM36=0),"",W36/BM36) | AG36: =IF(OR(Z36="",BM36="",BM36=0),"",Z36/BM36) | AH36: =IF(OR(AC36="",BM36="",BM36=0),"",AC36/BM36) | AI36: 75.5 | AJ36: 17.2 | AL36: 7.3 | AO36: 15.3 | AS36: 1.9 | BA36: 9.2 | BB36: 12.2 | BC36: 23.7 | BD36: 15.4 | BG36: 12 | BL36: Malayan Banking Berhad | Tenaga Nasional Berhad | Public Bank Berhad | Telekom Malaysia Berhad | Press Metal Aluminium Holdings Berhad | BM36: 6.9 | BN36: Low | BO36: Equity Malaysia Domestic 30% of the fund’s NAV | BQ36: 0.9072 | BR36: 2007-10-31 | BS36: 0.7059 | BT36: -22.19 | BU36: 6802
A37: PUBLIC SELECT TREASURES EQUITY FUND | B37: PSTEF | C37: Conventional | D37: Equity | E37: Capital Growth | F37: 5 | G37: Incidental | H37: 402.54 | I37: 22.07.2015 | J37: Qualified | K37: 80 | L37: 4/5 | M37: Qualified (WA: +4.24%) — YTD✘ 1Y✔ 3Y✔ 5Y✔ 10Y✔ | N37: 4.24 | O37: 5.15 | P37: 5.21 | Q37: -0.06 | R37: 23.87 | S37: 10.05 | T37: 13.82 | U37: 10.48 | V37: 7.54 | W37: 2.94 | X37: 3.45 | Y37: 2.15 | Z37: 1.3 | AA37: 7.29 | AB37: 2.85 | AC37: 4.44 | AD37: =IF(OR(Q37="",BM37="",BM37=0),"",Q37/BM37) | AE37: =IF(OR(T37="",BM37="",BM37=0),"",T37/BM37) | AF37: =IF(OR(W37="",BM37="",BM37=0),"",W37/BM37) | AG37: =IF(OR(Z37="",BM37="",BM37=0),"",Z37/BM37) | AH37: =IF(OR(AC37="",BM37="",BM37=0),"",AC37/BM37) | AI37: 74.8 | AJ37: 22.3 | AL37: 2.9 | AO37: 4.4 | AP37: 15 | AT37: 2.9 | BA37: 35.9 | BB37: 7.7 | BC37: 31.4 | BD37: 5.7 | BF37: 11.8 | BL37: Hon.Precision Incorporated | Kinik Company | TIME dotCom Berhad | IGB Real Estate Investment Trust | Frontken Corporation Berhad | BM37: 10.4 | BN37: High | BO37: Equity Malaysia Domestic 25% of the fund’s NAV | BQ37: 0.4931 | BR37: 2026-05-29 | BS37: 0.4776 | BT37: -3.14 | BU37: 17
A38: PUBLIC FAR-EAST SELECT FUND | B38: PFES | C38: Conventional | D38: Equity | E38: Capital Growth | F38: 5 | G38: Incidental | H38: 864.41 | I38: 22.11.2005 | J38: Qualified | K38: 80 | L38: 4/5 | M38: Qualified (WA: +4.19%) — YTD✔ 1Y✔ 3Y✔ 5Y✔ 10Y✘ | N38: 4.19 | O38: 22.42 | P38: 13.74 | Q38: 8.68 | R38: 55.4 | S38: 41.49 | T38: 13.91 | U38: 19.07 | V38: 15.79 | W38: 3.28 | X38: 3.56 | Y38: 2.09 | Z38: 1.47 | AA38: 7.62 | AB38: 7.7 | AC38: -0.08 | AD38: =IF(OR(Q38="",BM38="",BM38=0),"",Q38/BM38) | AE38: =IF(OR(T38="",BM38="",BM38=0),"",T38/BM38) | AF38: =IF(OR(W38="",BM38="",BM38=0),"",W38/BM38) | AG38: =IF(OR(Z38="",BM38="",BM38=0),"",Z38/BM38) | AH38: =IF(OR(AC38="",BM38="",BM38=0),"",AC38/BM38) | AI38: 0.9 | AJ38: 93.2 | AL38: 5.9 | AP38: 35.2 | AQ38: 26.8 | AU38: 30.5 | AZ38: 0.7 | BA38: 15.2 | BB38: 47.7 | BC38: 2.2 | BD38: 21.4 | BE38: 7.3 | BL38: Samsung Electronics Company Limited | Taiwan Semiconductor Manufacturing Company Limited | SK Hynix Incorporated | Alibaba Group Holding Limited - W | Tencent Holdings Limited | BM38: 17.7 | BN38: Very High | BO38: Equity Asia Pacific Asia | BP38: 2021 0.80 31.5.21 2.1 ThebenchmarkforPFESisacompositeof70%MSCIACFar-EastEx-JapanIndex 2022 0.80 31.5.22 2.7 and30%KualaLumpurCompositeIndex(priorto6July2009),30%FTSEBursa Malaysia KLCI (6 July 2009 to 29 April 2010). Note: Distribution yield simply measures the level of distributions and is MSCIACFar-EastEx-JapanIndex(30April2010to29April2021),S&PPanAsia not a measure of fund performance. Ex-Japan, Australia, New Zealand & India LargeCap Index (30 April 2021 to 1 January 2025), S&P Pan Asia Ex-Japan, Australia, New Zealand & India LargeCap 8% Capped Index (w.e.f. 2 January 2025). UnderlyingindexdataaresourcedfromS&PDowJonesIndices,LLCandLipper and expressed in Ringgit terms. | BQ38: 0.5227 | BR38: 2026-06-04 | BS38: 0.5015 | BT38: -4.06 | BU38: 11
A39: PB ASIA EQUITY FUND | B39: PBAEF | C39: Conventional | D39: Equity | E39: Capital Growth | F39: 5 | G39: Incidental | H39: 197.56 | I39: 27.06.2006 | J39: Qualified | K39: 100 | L39: 5/5 | M39: Qualified (WA: +4.01%) — YTD✔ 1Y✔ 3Y✔ 5Y✔ 10Y✔ | N39: 4.01 | O39: 26.67 | P39: 15.29 | Q39: 11.38 | R39: 56.42 | S39: 43.26 | T39: 13.16 | U39: 20 | V39: 16.79 | W39: 3.21 | X39: 5.47 | Y39: 5.06 | Z39: 0.41 | AA39: 8.73 | AB39: 8.2 | AC39: 0.53 | AD39: =IF(OR(Q39="",BM39="",BM39=0),"",Q39/BM39) | AE39: =IF(OR(T39="",BM39="",BM39=0),"",T39/BM39) | AF39: =IF(OR(W39="",BM39="",BM39=0),"",W39/BM39) | AG39: =IF(OR(Z39="",BM39="",BM39=0),"",Z39/BM39) | AH39: =IF(OR(AC39="",BM39="",BM39=0),"",AC39/BM39) | AI39: 0.8 | AJ39: 86.6 | AL39: 12.6 | AO39: 7.6 | AP39: 31.2 | AQ39: 28.1 | AR39: 5.4 | AU39: 14.3 | BA39: 28.8 | BB39: 36.2 | BC39: 3 | BD39: 14.5 | BE39: 4.9 | BL39: Taiwan Semiconductor Manufacturing Company Limited | Samsung Electronics Company Limited | HD Hyundai Electric Company Limited | Elite Material Company Limited | SK Hynix Incorporated | BM39: 16.5 | BN39: Very High | BO39: Equity Asia Pacific Asia | BP39: 2016 1.50 30.06.16 6.0 ThebenchmarkforPBAEFisacompositeof20%KualaLumpurCompositeIndex (priorto6July2009), 20%FTSE BursaMalaysiaKLCI(w.e.f.6July2009),20% 2017 1.50 30.06.17 4.9 TokyoStockPriceIndex(priorto30April2013),20%TOPIXCore30Index(w.e.f. 2018 1.50 29.06.18 5.3 30April 2013),20% KoreaCompositeStock PriceIndex(priorto30 April 2013), 20%KOSPI50Index(30April2013to29April2017),20%MSCIKoreaLargeCap 2019 1.00 28.06.19 3.7 Index (30 April 2017 to 29 April 2021), 20% S&P Korea LargeCap Index (w.e.f. 2020 1.75 30.06.20 6.0 30April2021)and40%MSCIGoldenDragonIndex(priorto30April2021),40% 2021 1.75 30.06.21 5.1 S&P Greater China LargeMidCap Index (30 April 2021 to 1 January2025), 40% S&P Greater China LargeMidCap 8% Capped Index (w.e.f. 2 January 2025). Note: Distribution yield simply measures the level of distributions and is not a measure of fund performance. UnderlyingindexdataaresourcedfromS&PDowJonesIndices,LLCandLipper and expressed in Ringgit terms. | BQ39: 0.5019 | BR39: 2026-06-04 | BS39: 0.4929 | BT39: -1.79 | BU39: 11
A40: PB ASIA-30 EQUITY FUND | B40: PBA30EF | C40: Conventional | D40: Equity | E40: Capital Growth | F40: 5 | G40: Incidental | H40: 337.92 | I40: 26.07.2018 | J40: Qualified | K40: 75 | L40: 3/4 | M40: Qualified (WA: +3.95%) — YTD✔ 1Y✔ 3Y✔ 5Y✘ | N40: 3.95 | O40: 26.03 | P40: 12.92 | Q40: 13.11 | R40: 55.74 | S40: 39.58 | T40: 16.16 | U40: 19.43 | V40: 17.82 | W40: 1.61 | X40: 2.06 | Y40: 3.52 | Z40: -1.46 | AD40: =IF(OR(Q40="",BM40="",BM40=0),"",Q40/BM40) | AE40: =IF(OR(T40="",BM40="",BM40=0),"",T40/BM40) | AF40: =IF(OR(W40="",BM40="",BM40=0),"",W40/BM40) | AG40: =IF(OR(Z40="",BM40="",BM40=0),"",Z40/BM40) | AH40: =IF(OR(AC40="",BM40="",BM40=0),"",AC40/BM40) | AJ40: 95.4 | AL40: 4.6 | AO40: 2.4 | AP40: 48 | AQ40: 30.2 | AR40: 0.7 | AU40: 14.1 | BA40: 24.1 | BB40: 50.4 | BD40: 18.5 | BE40: 2.4 | BL40: SK Hynix Incorporated | Taiwan Semiconductor Manufacturing Company Limited | Samsung Electronics Company Limited | Alibaba Group Holding Limited - W | Delta Electronics Incorporated | BM40: 20.3 | BN40: Very High | BO40: Equity Asia Pacific Asia | BQ40: 0.4564 | BR40: 2026-06-04 | BS40: 0.4345 | BT40: -4.8 | BU40: 11
...

Sheet Summary
A1: PUBLIC MUTUAL FUND SCREENER — SUMMARY | MFR April 2026
A3: SCREENING RESULTS
A4: Metric | B4: Value
A5: Total PHS files (all UT funds) | B5: 181
A6: Excluded: Class-B funds | B6: 6 | C6: (PeCDF-B, PMMF-B, PBCMF-B, PeICDF-B, PIMMF-B, PBICMF-B)
A7: Excluded: Wholesale funds | B7: 4 | C7: (PBCPF, PWSIF, PIWSIF, PeWS20F)
A8: Retail funds screened | B8: 171
A10: Funds qualified (Weighted Alpha > 0%) | B10: 134
A11: Funds disqualified | B11: 37
A12: Pass rate | B12: 78.4%
A13: Conventional funds qualified | B13: 86
A14: Shariah-compliant funds qualified | B14: 48
A16: Data source | B16: MFR April 2026
A17: Screening criteria | B17: Weighted Alpha > 0% (YTD×5% + 1Y×15% + 3Y×40% + 5Y×25% + 10Y×15%)
A18: Minimum data requirement | B18: ≥2 periods (YTD, 1Y, 3Y, 5Y, 10Y)
A19: Note | B19: Class-B & Wholesale funds excluded — not available to typical retail investors
A21: BREAKDOWN BY FUND TYPE
A22: Fund Type | B22: Qualified | C22: 100% Rate | D22: Shariah | E22: Conventional
A23: Equity | B23: =COUNTIFS(Master!J$4:J$174,"Qualified",Master!D$4:D$174,"Equity") | C23: =COUNTIFS(Master!J$4:J$174,"Qualified",Master!D$4:D$174,"Equity",Master!K$4:K$174,100) | D23: =COUNTIFS(Master!J$4:J$174,"Qualified",Master!D$4:D$174,"Equity",Master!C$4:C$174,"Shariah") | E23: =B23-D23
A24: Mixed Asset / Balanced | B24: =COUNTIFS(Master!J$4:J$174,"Qualified",Master!D$4:D$174,"Mixed Asset / Balanced") | C24: =COUNTIFS(Master!J$4:J$174,"Qualified",Master!D$4:D$174,"Mixed Asset / Balanced",Master!K$4:K$174,100) | D24: =COUNTIFS(Master!J$4:J$174,"Qualified",Master!D$4:D$174,"Mixed Asset / Balanced",Master!C$4:C$174,"Shariah") | E24: =B24-D24
A25: Fixed Income | B25: =COUNTIFS(Master!J$4:J$174,"Qualified",Master!D$4:D$174,"Fixed Income") | C25: =COUNTIFS(Master!J$4:J$174,"Qualified",Master!D$4:D$174,"Fixed Income",Master!K$4:K$174,100) | D25: =COUNTIFS(Master!J$4:J$174,"Qualified",Master!D$4:D$174,"Fixed Income",Master!C$4:C$174,"Shariah") | E25: =B25-D25
A26: Fund of Funds | B26: =COUNTIFS(Master!J$4:J$174,"Qualified",Master!D$4:D$174,"Fund of Funds") | C26: =COUNTIFS(Master!J$4:J$174,"Qualified",Master!D$4:D$174,"Fund of Funds",Master!K$4:K$174,100) | D26: =COUNTIFS(Master!J$4:J$174,"Qualified",Master!D$4:D$174,"Fund of Funds",Master!C$4:C$174,"Shariah") | E26: =B26-D26
A27: Money Market | B27: =COUNTIFS(Master!J$4:J$174,"Qualified",Master!D$4:D$174,"Money Market") | C27: =COUNTIFS(Master!J$4:J$174,"Qualified",Master!D$4:D$174,"Money Market",Master!K$4:K$174,100) | D27: =COUNTIFS(Master!J$4:J$174,"Qualified",Master!D$4:D$174,"Money Market",Master!C$4:C$174,"Shariah") | E27: =B27-D27
A28: TOTAL | B28: =SUM(B23:B27) | C28: =SUM(C23:C27) | D28: =SUM(D23:D27) | E28: =SUM(E23:E27)
A30: EQUITY — MEDIAN STATISTICS
A31: Metric | B31: YTD (%) | C31: 1Y (%) | D31: 3Y Ann. (%) | E31: 5Y Ann. (%) | F31: 10Y Ann. (%) | G31: 3Y Alpha (%) | H31: Beat (%)
A32: Median | B32: =IFERROR(MEDIAN(FILTER(Master!O$4:O$174,(Master!J$4:J$174="Qualified")*(Master!D$4:D$174="Equity"))),"") | C32: =IFERROR(MEDIAN(FILTER(Master!R$4:R$174,(Master!J$4:J$174="Qualified")*(Master!D$4:D$174="Equity"))),"") | D32: =IFERROR(MEDIAN(FILTER(Master!U$4:U$174,(Master!J$4:J$174="Qualified")*(Master!D$4:D$174="Equity"))),"") | E32: =IFERROR(MEDIAN(FILTER(Master!X$4:X$174,(Master!J$4:J$174="Qualified")*(Master!D$4:D$174="Equity"))),"") | F32: =IFERROR(MEDIAN(FILTER(Master!AA$4:AA$174,(Master!J$4:J$174="Qualified")*(Master!D$4:D$174="Equity"))),"") | G32: =IFERROR(MEDIAN(FILTER(Master!W$4:W$174,(Master!J$4:J$174="Qualified")*(Master!D$4:D$174="Equity"))),"") | H32: =IFERROR(MEDIAN(FILTER(Master!K$4:K$174,(Master!J$4:J$174="Qualified")*(Master!D$4:D$174="Equity"))),"")
A34: EQUITY — TOP 5 BY 3Y ANN. FUND RETURN
A35: Fund Name | B35: Abbr | C35: 3Y Fund (%) | D35: 3Y Alpha (%) | E35: Beat (%) | F35: AUM (RM M) | G35: VC
A36: =IFERROR(INDEX(SORT(FILTER({Master!A$4:A$174,Master!B$4:B$174,Master!U$4:U$174,Master!W$4:W$174,Master!K$4:K$174,Master!H$4:H$174,Master!BN$4:BN$174},Master!J$4:J$174="Qualified",Master!D$4:D$174="Equity",Master!U$4:U$174<>""),3,FALSE),1,1),"") | B36: =IFERROR(INDEX(SORT(FILTER({Master!A$4:A$174,Master!B$4:B$174,Master!U$4:U$174,Master!W$4:W$174,Master!K$4:K$174,Master!H$4:H$174,Master!BN$4:BN$174},Master!J$4:J$174="Qualified",Master!D$4:D$174="Equity",Master!U$4:U$174<>""),3,FALSE),1,2),"") | C36: =IFERROR(INDEX(SORT(FILTER({Master!A$4:A$174,Master!B$4:B$174,Master!U$4:U$174,Master!W$4:W$174,Master!K$4:K$174,Master!H$4:H$174,Master!BN$4:BN$174},Master!J$4:J$174="Qualified",Master!D$4:D$174="Equity",Master!U$4:U$174<>""),3,FALSE),1,3),"") | D36: =IFERROR(INDEX(SORT(FILTER({Master!A$4:A$174,Master!B$4:B$174,Master!U$4:U$174,Master!W$4:W$174,Master!K$4:K$174,Master!H$4:H$174,Master!BN$4:BN$174},Master!J$4:J$174="Qualified",Master!D$4:D$174="Equity",Master!U$4:U$174<>""),3,FALSE),1,4),"") | E36: =IFERROR(INDEX(SORT(FILTER({Master!A$4:A$174,Master!B$4:B$174,Master!U$4:U$174,Master!W$4:W$174,Master!K$4:K$174,Master!H$4:H$174,Master!BN$4:BN$174},Master!J$4:J$174="Qualified",Master!D$4:D$174="Equity",Master!U$4:U$174<>""),3,FALSE),1,5),"") | F36: =IFERROR(INDEX(SORT(FILTER({Master!A$4:A$174,Master!B$4:B$174,Master!U$4:U$174,Master!W$4:W$174,Master!K$4:K$174,Master!H$4:H$174,Master!BN$4:BN$174},Master!J$4:J$174="Qualified",Master!D$4:D$174="Equity",Master!U$4:U$174<>""),3,FALSE),1,6),"") | G36: =IFERROR(INDEX(SORT(FILTER({Master!A$4:A$174,Master!B$4:B$174,Master!U$4:U$174,Master!W$4:W$174,Master!K$4:K$174,Master!H$4:H$174,Master!BN$4:BN$174},Master!J$4:J$174="Qualified",Master!D$4:D$174="Equity",Master!U$4:U$174<>""),3,FALSE),1,7),"")
A37: =IFERROR(INDEX(SORT(FILTER({Master!A$4:A$174,Master!B$4:B$174,Master!U$4:U$174,Master!W$4:W$174,Master!K$4:K$174,Master!H$4:H$174,Master!BN$4:BN$174},Master!J$4:J$174="Qualified",Master!D$4:D$174="Equity",Master!U$4:U$174<>""),3,FALSE),2,1),"") | B37: =IFERROR(INDEX(SORT(FILTER({Master!A$4:A$174,Master!B$4:B$174,Master!U$4:U$174,Master!W$4:W$174,Master!K$4:K$174,Master!H$4:H$174,Master!BN$4:BN$174},Master!J$4:J$174="Qualified",Master!D$4:D$174="Equity",Master!U$4:U$174<>""),3,FALSE),2,2),"") | C37: =IFERROR(INDEX(SORT(FILTER({Master!A$4:A$174,Master!B$4:B$174,Master!U$4:U$174,Master!W$4:W$174,Master!K$4:K$174,Master!H$4:H$174,Master!BN$4:BN$174},Master!J$4:J$174="Qualified",Master!D$4:D$174="Equity",Master!U$4:U$174<>""),3,FALSE),2,3),"") | D37: =IFERROR(INDEX(SORT(FILTER({Master!A$4:A$174,Master!B$4:B$174,Master!U$4:U$174,Master!W$4:W$174,Master!K$4:K$174,Master!H$4:H$174,Master!BN$4:BN$174},Master!J$4:J$174="Qualified",Master!D$4:D$174="Equity",Master!U$4:U$174<>""),3,FALSE),2,4),"") | E37: =IFERROR(INDEX(SORT(FILTER({Master!A$4:A$174,Master!B$4:B$174,Master!U$4:U$174,Master!W$4:W$174,Master!K$4:K$174,Master!H$4:H$174,Master!BN$4:BN$174},Master!J$4:J$174="Qualified",Master!D$4:D$174="Equity",Master!U$4:U$174<>""),3,FALSE),2,5),"") | F37: =IFERROR(INDEX(SORT(FILTER({Master!A$4:A$174,Master!B$4:B$174,Master!U$4:U$174,Master!W$4:W$174,Master!K$4:K$174,Master!H$4:H$174,Master!BN$4:BN$174},Master!J$4:J$174="Qualified",Master!D$4:D$174="Equity",Master!U$4:U$174<>""),3,FALSE),2,6),"") | G37: =IFERROR(INDEX(SORT(FILTER({Master!A$4:A$174,Master!B$4:B$174,Master!U$4:U$174,Master!W$4:W$174,Master!K$4:K$174,Master!H$4:H$174,Master!BN$4:BN$174},Master!J$4:J$174="Qualified",Master!D$4:D$174="Equity",Master!U$4:U$174<>""),3,FALSE),2,7),"")
